Workbook
Name _1Excel_BuiltIn__FilterDatabase_8_1: 'crn stok listesi'!$A$1:$D$180
Name _1Excel_BuiltIn__FilterDatabase_8_1: 'crn stok listesi (2)'!$A$1:$D$180
Name _1Excel_BuiltIn__FilterDatabase_8_1: LİSTE!$B$1:$T$288
Name _1Excel_BuiltIn__FilterDatabase_8_1: SatışFiyat!$A$1:$D$209
Name Excel_BuiltIn__FilterDatabase_8: #REF!
Name Excel_BuiltIn__FilterDatabase_8: #REF!
Name Excel_BuiltIn__FilterDatabase_8: #REF!
Name Excel_BuiltIn__FilterDatabase_8: #REF!
Name Excel_BuiltIn__FilterDatabase_8: #REF!
Name Excel_BuiltIn__FilterDatabase_8: #REF!
Name Excel_BuiltIn__FilterDatabase_8: #REF!
Name Guncel: Sayfa1!$A$2:$F$169

Sheet Sayfa2
C1: SAC FİYATI | D1: MAŞON FİYATI | E1: TUTACAK FİYATI | F1: SON KAPAMA ÇAPI | G1: Pİ | H1: BOYU | I1: KULLANILAN SAC m | J1: SON KAPAMA İZOLESİ 1msinin fiyatı | K1: TUTARI | M1: ÇAPI | N1: Pİ | O1: KALINLIK | P1: YOĞUNLUK | Q1: AĞIRLIĞI (KG) | R1: ÇAPI | S1: Pİ | T1: KALINLIK | U1: YOĞUNLUK | V1: AĞIRLIĞI (KG) | W1: ÇAPI | X1: Pİ | Y1: KALINLIK | Z1: YOĞUNLUK | AA1: AĞIRLIĞI (KG) | AB1: ÇAPI | AC1: Pİ | AD1: KALINLIK | AE1: YOĞUNLUK | AF1: AĞIRLIĞI (KG) | AG1: ÇAPI | AH1: Pİ | AI1: KALINLIK | AJ1: YOĞUNLUK | AK1: AĞIRLIĞI (KG) | AM1: İZOLASYON | AN1: TAŞ YÜNÜ + MODUL (CM ) | AO1: Pİ | AP1: mm | AQ1: 430 Metresi $ | AR1: $ | AS1: mm | AT1: DIŞ CİDAR | AV1: Pİ | AW1: Kalınlık | AX1: Yogunluk | AY1: Metresi | AZ1: $ | BA1: TOPLAM İZOLASYON+ KILIF | BB1: SACIN M FİYATI | BC1: TOPLAM | BE1: KELEPÇE | BF1: ÇAPI | BG1: Pİ | BH1: Birim maliyet $ | BJ1: kelepçe kulağı | BK1: $ | BL1: İZOLELİ KELEPÇE | BM1: ÇAPI | BN1: İZOLE | BP1: Pİ | BR1: Birim maliyet $ | BT1: DUVAR KELEPÇE | BW1: Birim maliyet $ (7cm sac kullanıldı. ) | BY1: VİDA | BZ1: MALİYETİ | CA1: DUVAR KELEPÇESİ + İZOLE | CB1: ÇAP | CC1: MALİYETİ | CD1: SIVAMA ÇAP $ | CF1: SIVAMA İŞCİLİĞİ | CG1: TOPLAM | CJ1: Düz Modül 250 mm | CL1: CONTA | CM1: ÇAPI | CN1: Pİ | CP1: MALİYET $ | CR1: SEHPA | CS1: Cevre profil | CT1: Toplam Ayak Profil (m)
B2: 1000 | C2: 6.5 | D2: 1.39 | E2: 0.5 | F2: 100 | G2: 3.14 | H2: 0.25 | I2: =G2*F2*H2/1000 -> 0.0785 | J2: =BC2 -> 4.578905 | K2: =H2*J2 -> 1.1447263 | L2: 100 | M2: 100 | N2: 3.14 | O2: 0.4 | P2: 0.8 | Q2: =M2*N2*O2*P2/100 -> 1.0048 | R2: 100 | S2: 3.14 | T2: 0.5 | U2: 0.8 | V2: =R2*S2*T2*U2/100 -> 1.256 | W2: 100 | X2: 3.14 | Y2: 0.6 | Z2: 0.8 | AA2: =W2*X2*Y2*Z2/100 -> 1.5072 | AB2: 100 | AC2: 3.14 | AD2: 0.8 | AE2: 0.8 | AF2: =AB2*AC2*AD2*AE2/100 -> 2.0096 | AG2: 100 | AH2: 3.14 | AI2: 1 | AJ2: 0.8 | AK2: =AG2*AH2*AI2*AJ2/100 -> 2.512 | AM2: 100 | AN2: =R2+25 -> 125 | AO2: 3.14 | AP2: =AN2*AO2/1000 -> 0.3925 | AQ2: 2.45 | AR2: =AP2*AQ2 -> 0.961625 | AS2: 55 | AT2: =AN2+AS2 -> 180 | AU2: =AT2-AM2 -> 80 | AV2: 3.14 | AW2: 0.4 | AX2: 0.8 | AY2: 2 | AZ2: =AT2*AV2*AY2*AW2*AX2/100 -> 3.61728 | BA2: =AZ2+AR2 -> 4.578905 | BB2: 0 | BC2: =BA2+BB2 -> 4.578905 | BE2: 100 | BF2: 100 | BG2: 3.14 | BH2: 0.66 | BI2: =BG2*BF2*BH2/1000 -> 0.20724 | BJ2: =2.5/7.7 -> 0.32467532 | BK2: =BI2+BJ2 -> 0.53191532 | BL2: 100 | BM2: 100 | BN2: 50 | BO2: =BM2+BN2 -> 150 | BP2: 3.14 | BQ2: =BO2*BP2/1000 -> 0.471 | BR2: 0.66 | BS2: =BQ2*BR2 -> 0.31086 | BT2: 100 | BU2: 100 | BV2: 3.14 | BW2: 1.3 | BX2: =BV2*BU2*BW2/1000 -> 0.4082 | BY2: 0.78 | BZ2: =BX2+BY2 -> 1.1882 | CA2: 100 | CB2: =CA2+50 -> 150 | CC2: =BZ5 -> 1.3923 | CD2: 100 | CE2: 0.57 | CF2: 0.68 | CG2: =CE2+CF2 -> 1.25 | CH2: Ø100Son kapama İzoleli | CI2: 1.005 | CJ2: Ø100Standart Düz Modül 250 mm | CK2: 1.005 | CL2: 100 | CM2: 100 | CN2: 3.14 | CO2: =6/7.3 -> 0.82191781 | CP2: =CM2*CN2*CO2/1000 -> 0.25808219 | CQ2: 8 | CR2: 100 | CS2: =$CQ$2*CR2/1000 -> 0.8 | CT2: 2 | CU2: =CS2+CT2 -> 2.8
F3: 130 | G3: 3.14 | H3: 0.25 | I3: =G3*F3*H3/1000 -> 0.10205 | J3: =BC3 -> 5.412575 | K3: =H3*J3 -> 1.3531438 | L3: 130 | M3: 130 | N3: 3.14 | O3: 0.4 | P3: 0.8 | Q3: =M3*N3*O3*P3/100 -> 1.30624 | R3: 130 | S3: 3.14 | T3: 0.5 | U3: 0.8 | V3: =R3*S3*T3*U3/100 -> 1.6328 | W3: 130 | X3: 3.14 | Y3: 0.6 | Z3: 0.8 | AA3: =W3*X3*Y3*Z3/100 -> 1.95936 | AB3: 130 | AC3: 3.14 | AD3: 0.8 | AE3: 0.8 | AF3: =AB3*AC3*AD3*AE3/100 -> 2.61248 | AG3: 130 | AH3: 3.14 | AI3: 1 | AJ3: 0.8 | AK3: =AG3*AH3*AI3*AJ3/100 -> 3.2656 | AM3: 130 | AN3: 155 | AO3: 3.14 | AP3: =AN3*AO3/1000 -> 0.4867 | AQ3: 2.45 | AR3: =AP3*AQ3 -> 1.192415 | AS3: 55 | AT3: =AN3+AS3 -> 210 | AU3: =AT3-AM3 -> 80 | AV3: 3.14 | AW3: 0.4 | AX3: 0.8 | AY3: 2 | AZ3: =AT3*AV3*AY3*AW3*AX3/100 -> 4.22016 | BA3: =AZ3+AR3 -> 5.412575 | BB3: 0 | BC3: =BA3+BB3 -> 5.412575 | BE3: 130 | BF3: 130 | BG3: 3.14 | BH3: 0.66 | BI3: =BG3*BF3*BH3/1000 -> 0.269412 | BJ3: =2.5/7.7 -> 0.32467532 | BK3: =BI3+BJ3 -> 0.59408732 | BT3: 130 | BU3: 130 | BV3: 3.14 | BW3: 1.3 | BX3: =BV3*BU3*BW3/1000 -> 0.53066 | BY3: 0.78 | BZ3: =BX3+BY3 -> 1.31066 | CA3: 130 | CB3: 180 | CC3: =BZ6 -> 1.51476 | CD3: 130 | CE3: 0.57 | CF3: 0.68 | CG3: =CE3+CF3 -> 1.25 | CH3: Ø130Son kapama İzoleli | CI3: 1.30624 | CJ3: Ø130Standart Düz Modül 250 mm | CK3: 1.30624 | CL3: 130 | CM3: 130 | CN3: 3.14 | CO3: =6/7.3 -> 0.82191781 | CP3: =CM3*CN3*CO3/1000 -> 0.33550685 | CR3: 130 | CS3: =$CQ$2*CR3/1000 -> 1.04 | CT3: 2 | CU3: =CS3+CT3 -> 3.04
B4: 500 | C4: =C2/2 -> 3.25 | F4: 140 | G4: 3.14 | H4: 0.25 | I4: =G4*F4*H4/1000 -> 0.1099 | J4: =BC4 -> 5.690465 | K4: =H4*J4 -> 1.4226163 | L4: 140 | M4: 140 | N4: 3.14 | O4: 0.4 | P4: 0.8 | Q4: =M4*N4*O4*P4/100 -> 1.40672 | R4: 140 | S4: 3.14 | T4: 0.5 | U4: 0.8 | V4: =R4*S4*T4*U4/100 -> 1.7584 | W4: 140 | X4: 3.14 | Y4: 0.6 | Z4: 0.8 | AA4: =W4*X4*Y4*Z4/100 -> 2.11008 | AB4: 140 | AC4: 3.14 | AD4: 0.8 | AE4: 0.8 | AF4: =AB4*AC4*AD4*AE4/100 -> 2.81344 | AG4: 140 | AH4: 3.14 | AI4: 1 | AJ4: 0.8 | AK4: =AG4*AH4*AI4*AJ4/100 -> 3.5168 | AM4: 140 | AN4: =R4+25 -> 165 | AO4: 3.14 | AP4: =AN4*AO4/1000 -> 0.5181 | AQ4: 2.45 | AR4: =AP4*AQ4 -> 1.269345 | AS4: 55 | AT4: =AN4+AS4 -> 220 | AU4: =AT4-AM4 -> 80 | AV4: 3.14 | AW4: 0.4 | AX4: 0.8 | AY4: 2 | AZ4: =AT4*AV4*AY4*AW4*AX4/100 -> 4.42112 | BA4: =AZ4+AR4 -> 5.690465 | BB4: 0 | BC4: =BA4+BB4 -> 5.690465 | BE4: 140 | BF4: 140 | BG4: 3.14 | BH4: 0.66 | BI4: =BG4*BF4*BH4/1000 -> 0.290136 | BJ4: =2.5/7.7 -> 0.32467532 | BK4: =BI4+BJ4 -> 0.61481132 | BL4: 140 | BM4: 140 | BN4: 50 | BO4: =BM4+BN4 -> 190 | BP4: 3.14 | BQ4: =BO4*BP4/1000 -> 0.5966 | BR4: 0.66 | BS4: =BQ4*BR4 -> 0.393756 | BT4: 140 | BU4: 140 | BV4: 3.14 | BW4: 1.3 | BX4: =BV4*BU4*BW4/1000 -> 0.57148 | BY4: 0.78 | BZ4: =BX4+BY4 -> 1.35148 | CA4: 140 | CB4: =CA4+50 -> 190 | CC4: =BZ7 -> 1.5964 | CD4: 140 | CE4: 0.57 | CF4: 0.68 | CG4: =CE4+CF4 -> 1.25 | CH4: Ø140Son kapama İzoleli | CI4: 1.407 | CJ4: Ø140Standart Düz Modül 250 mm | CK4: 1.407 | CL4: 140 | CM4: 140 | CN4: 3.14 | CO4: =6/7.3 -> 0.82191781 | CP4: =CM4*CN4*CO4/1000 -> 0.36131507 | CR4: 140 | CS4: =$CQ$2*CR4/1000 -> 1.12 | CT4: 2 | CU4: =CS4+CT4 -> 3.12
B5: 250 | C5: =C2/4 -> 1.625 | F5: 150 | G5: 3.14 | H5: 0.25 | I5: =G5*F5*H5/1000 -> 0.11775 | J5: =BC5 -> 5.968355 | K5: =H5*J5 -> 1.4920888 | L5: 150 | M5: 150 | N5: 3.14 | O5: 0.4 | P5: 0.8 | Q5: =M5*N5*O5*P5/100 -> 1.5072 | R5: 150 | S5: 3.14 | T5: 0.5 | U5: 0.8 | V5: =R5*S5*T5*U5/100 -> 1.884 | W5: 150 | X5: 3.14 | Y5: 0.6 | Z5: 0.8 | AA5: =W5*X5*Y5*Z5/100 -> 2.2608 | AB5: 150 | AC5: 3.14 | AD5: 0.8 | AE5: 0.8 | AF5: =AB5*AC5*AD5*AE5/100 -> 3.0144 | AG5: 150 | AH5: 3.14 | AI5: 1 | AJ5: 0.8 | AK5: =AG5*AH5*AI5*AJ5/100 -> 3.768 | AM5: 150 | AN5: =R5+25 -> 175 | AO5: 3.14 | AP5: =AN5*AO5/1000 -> 0.5495 | AQ5: 2.45 | AR5: =AP5*AQ5 -> 1.346275 | AS5: 55 | AT5: =AN5+AS5 -> 230 | AU5: =AT5-AM5 -> 80 | AV5: 3.14 | AW5: 0.4 | AX5: 0.8 | AY5: 2 | AZ5: =AT5*AV5*AY5*AW5*AX5/100 -> 4.62208 | BA5: =AZ5+AR5 -> 5.968355 | BB5: 0 | BC5: =BA5+BB5 -> 5.968355 | BE5: 150 | BF5: 150 | BG5: 3.14 | BH5: 0.66 | BI5: =BG5*BF5*BH5/1000 -> 0.31086 | BJ5: =2.5/7.7 -> 0.32467532 | BK5: =BI5+BJ5 -> 0.63553532 | BL5: 150 | BM5: 150 | BN5: 50 | BO5: =BM5+BN5 -> 200 | BP5: 3.14 | BQ5: =BO5*BP5/1000 -> 0.628 | BR5: 0.66 | BS5: =BQ5*BR5 -> 0.41448 | BT5: 150 | BU5: 150 | BV5: 3.14 | BW5: 1.3 | BX5: =BV5*BU5*BW5/1000 -> 0.6123 | BY5: 0.78 | BZ5: =BX5+BY5 -> 1.3923 | CA5: 150 | CB5: =CA5+50 -> 200 | CC5: =BZ8 -> 1.69845 | CD5: 150 | CE5: 0.64 | CF5: 0.68 | CG5: =CE5+CF5 -> 1.32 | CH5: Ø150Son kapama İzoleli | CI5: 1.507 | CJ5: Ø150Standart Düz Modül 250 mm | CK5: 1.507 | CL5: 150 | CM5: 150 | CN5: 3.14 | CO5: =6/7.3 -> 0.82191781 | CP5: =CM5*CN5*CO5/1000 -> 0.38712329 | CR5: 150 | CS5: =$CQ$2*CR5/1000 -> 1.2 | CT5: 2 | CU5: =CS5+CT5 -> 3.2
B6: DİRSEK | F6: 180 | G6: 3.14 | H6: 0.25 | I6: =G6*F6*H6/1000 -> 0.1413 | J6: =BC6 -> 6.802025 | K6: =H6*J6 -> 1.7005062 | L6: 180 | M6: 180 | N6: 3.14 | O6: 0.4 | P6: 0.8 | Q6: =M6*N6*O6*P6/100 -> 1.80864 | R6: 180 | S6: 3.14 | T6: 0.5 | U6: 0.8 | V6: =R6*S6*T6*U6/100 -> 2.2608 | W6: 180 | X6: 3.14 | Y6: 0.6 | Z6: 0.8 | AA6: =W6*X6*Y6*Z6/100 -> 2.71296 | AB6: 180 | AC6: 3.14 | AD6: 0.8 | AE6: 0.8 | AF6: =AB6*AC6*AD6*AE6/100 -> 3.61728 | AG6: 180 | AH6: 3.14 | AI6: 1 | AJ6: 0.8 | AK6: =AG6*AH6*AI6*AJ6/100 -> 4.5216 | AM6: 180 | AN6: =R6+25 -> 205 | AO6: 3.14 | AP6: =AN6*AO6/1000 -> 0.6437 | AQ6: 2.45 | AR6: =AP6*AQ6 -> 1.577065 | AS6: 55 | AT6: =AN6+AS6 -> 260 | AU6: =AT6-AM6 -> 80 | AV6: 3.14 | AW6: 0.4 | AX6: 0.8 | AY6: 2 | AZ6: =AT6*AV6*AY6*AW6*AX6/100 -> 5.22496 | BA6: =AZ6+AR6 -> 6.802025 | BB6: 0 | BC6: =BA6+BB6 -> 6.802025 | BE6: 180 | BF6: 180 | BG6: 3.14 | BH6: 0.66 | BI6: =BG6*BF6*BH6/1000 -> 0.373032 | BJ6: =2.5/7.7 -> 0.32467532 | BK6: =BI6+BJ6 -> 0.69770732 | BL6: 180 | BM6: 180 | BN6: 50 | BO6: =BM6+BN6 -> 230 | BP6: 3.14 | BQ6: =BO6*BP6/1000 -> 0.7222 | BR6: 0.66 | BS6: =BQ6*BR6 -> 0.476652 | BT6: 180 | BU6: 180 | BV6: 3.14 | BW6: 1.3 | BX6: =BV6*BU6*BW6/1000 -> 0.73476 | BY6: 0.78 | BZ6: =BX6+BY6 -> 1.51476 | CA6: 180 | CB6: =CA6+50 -> 230 | CC6: =BZ9 -> 1.75968 | CD6: 180 | CE6: 0.8 | CF6: 0.68 | CG6: =CE6+CF6 -> 1.48 | CH6: Ø180Son kapama İzoleli | CI6: 1.809 | CJ6: Ø180Standart Düz Modül 250 mm | CK6: 1.809 | CL6: 180 | CM6: 180 | CN6: 3.14 | CO6: =6/7.3 -> 0.82191781 | CP6: =CM6*CN6*CO6/1000 -> 0.46454795 | CR6: 180 | CS6: =$CQ$2*CR6/1000 -> 1.44 | CT6: 2 | CU6: =CS6+CT6 -> 3.44
A7: 15 | B7: 1 | C7: =C2*B7 -> 6.5 | F7: 200 | G7: 3.14 | H7: 0.25 | I7: =G7*F7*H7/1000 -> 0.157 | J7: =BC7 -> 7.357805 | K7: =H7*J7 -> 1.8394513 | L7: 200 | M7: 200 | N7: 3.14 | O7: 0.4 | P7: 0.8 | Q7: =M7*N7*O7*P7/100 -> 2.0096 | R7: 200 | S7: 3.14 | T7: 0.5 | U7: 0.8 | V7: =R7*S7*T7*U7/100 -> 2.512 | W7: 200 | X7: 3.14 | Y7: 0.6 | Z7: 0.8 | AA7: =W7*X7*Y7*Z7/100 -> 3.0144 | AB7: 200 | AC7: 3.14 | AD7: 0.8 | AE7: 0.8 | AF7: =AB7*AC7*AD7*AE7/100 -> 4.0192 | AG7: 200 | AH7: 3.14 | AI7: 1 | AJ7: 0.8 | AK7: =AG7*AH7*AI7*AJ7/100 -> 5.024 | AM7: 200 | AN7: =R7+25 -> 225 | AO7: 3.14 | AP7: =AN7*AO7/1000 -> 0.7065 | AQ7: 2.45 | AR7: =AP7*AQ7 -> 1.730925 | AS7: 55 | AT7: =AN7+AS7 -> 280 | AU7: =AT7-AM7 -> 80 | AV7: 3.14 | AW7: 0.4 | AX7: 0.8 | AY7: 2 | AZ7: =AT7*AV7*AY7*AW7*AX7/100 -> 5.62688 | BA7: =AZ7+AR7 -> 7.357805 | BB7: 0 | BC7: =BA7+BB7 -> 7.357805 | BE7: 200 | BF7: 200 | BG7: 3.14 | BH7: 0.66 | BI7: =BG7*BF7*BH7/1000 -> 0.41448 | BJ7: =2.5/7.7 -> 0.32467532 | BK7: =BI7+BJ7 -> 0.73915532 | BL7: 200 | BM7: 200 | BN7: 50 | BO7: =BM7+BN7 -> 250 | BP7: 3.14 | BQ7: =BO7*BP7/1000 -> 0.785 | BR7: 0.66 | BS7: =BQ7*BR7 -> 0.5181 | BT7: 200 | BU7: 200 | BV7: 3.14 | BW7: 1.3 | BX7: =BV7*BU7*BW7/1000 -> 0.8164 | BY7: 0.78 | BZ7: =BX7+BY7 -> 1.5964 | CA7: 200 | CB7: =CA7+50 -> 250 | CC7: =BZ10 -> 1.8005 | CD7: 200 | CE7: 0.8 | CF7: 0.68 | CG7: =CE7+CF7 -> 1.48 | CH7: Ø200Son kapama İzoleli | CI7: 2.01 | CJ7: Ø200Standart Düz Modül 250 mm | CK7: 2.261 | CL7: 200 | CM7: 200 | CN7: 3.14 | CO7: =6/7.3 -> 0.82191781 | CP7: =CM7*CN7*CO7/1000 -> 0.51616438 | CR7: 200 | CS7: =$CQ$2*CR7/1000 -> 1.6 | CT7: 2 | CU7: =CS7+CT7 -> 3.6
A8: 30 | B8: 1 | C8: =C2*B8 -> 6.5 | F8: 225 | G8: 3.14 | H8: 0.25 | I8: =G8*F8*H8/1000 -> 0.176625 | J8: =BC8 -> 7.635695 | K8: =H8*J8 -> 1.9089238 | L8: 225 | M8: 225 | N8: 3.14 | O8: 0.4 | P8: 0.8 | Q8: =M8*N8*O8*P8/100 -> 2.2608 | R8: 210 | S8: 3.14 | T8: 0.5 | U8: 0.8 | V8: =R8*S8*T8*U8/100 -> 2.6376 | W8: 210 | X8: 3.14 | Y8: 0.6 | Z8: 0.8 | AA8: =W8*X8*Y8*Z8/100 -> 3.16512 | AB8: 210 | AC8: 3.14 | AD8: 0.8 | AE8: 0.8 | AF8: =AB8*AC8*AD8*AE8/100 -> 4.22016 | AG8: 210 | AH8: 3.14 | AI8: 1 | AJ8: 0.8 | AK8: =AG8*AH8*AI8*AJ8/100 -> 5.2752 | AM8: 225 | AN8: =R8+25 -> 235 | AO8: 3.14 | AP8: =AN8*AO8/1000 -> 0.7379 | AQ8: 2.45 | AR8: =AP8*AQ8 -> 1.807855 | AS8: 55 | AT8: =AN8+AS8 -> 290 | AU8: =AT8-AM8 -> 65 | AV8: 3.14 | AW8: 0.4 | AX8: 0.8 | AY8: 2 | AZ8: =AT8*AV8*AY8*AW8*AX8/100 -> 5.82784 | BA8: =AZ8+AR8 -> 7.635695 | BB8: 0 | BC8: =BA8+BB8 -> 7.635695 | BE8: 225 | BF8: 225 | BG8: 3.14 | BH8: 0.66 | BI8: =BG8*BF8*BH8/1000 -> 0.46629 | BJ8: =2.5/7.7 -> 0.32467532 | BK8: =BI8+BJ8 -> 0.79096532 | BL8: 225 | BM8: 225 | BN8: 50 | BO8: =BM8+BN8 -> 275 | BP8: 3.14 | BQ8: =BO8*BP8/1000 -> 0.8635 | BR8: 0.66 | BS8: =BQ8*BR8 -> 0.56991 | BT8: 225 | BU8: 225 | BV8: 3.14 | BW8: 1.3 | BX8: =BV8*BU8*BW8/1000 -> 0.91845 | BY8: 0.78 | BZ8: =BX8+BY8 -> 1.69845 | CA8: 225 | CB8: =CA8+50 -> 275 | CC8: =BZ12 -> 1.92296 | CD8: 225 | CE8: 0.96 | CF8: 0.68 | CG8: =CE8+CF8 -> 1.64 | CH8: Ø225Son kapama İzoleli | CI8: 2.261 | CJ8: Ø225Standart Düz Modül 250 mm | CK8: 2.412 | CL8: 225 | CM8: 225 | CN8: 3.14 | CO8: =6/7.3 -> 0.82191781 | CP8: =CM8*CN8*CO8/1000 -> 0.58068493 | CR8: 225 | CS8: =$CQ$2*CR8/1000 -> 1.8 | CT8: 2 | CU8: =CS8+CT8 -> 3.8
A9: 45 | B9: 1 | C9: =C2*B9 -> 6.5 | F9: 240 | G9: 3.14 | H9: 0.25 | I9: =G9*F9*H9/1000 -> 0.1884 | J9: =BC9 -> 8.469365 | K9: =H9*J9 -> 2.1173413 | L9: 240 | M9: 240 | N9: 3.14 | O9: 0.4 | P9: 0.8 | Q9: =M9*N9*O9*P9/100 -> 2.41152 | R9: 240 | S9: 3.14 | T9: 0.5 | U9: 0.8 | V9: =R9*S9*T9*U9/100 -> 3.0144 | W9: 240 | X9: 3.14 | Y9: 0.6 | Z9: 0.8 | AA9: =W9*X9*Y9*Z9/100 -> 3.61728 | AB9: 240 | AC9: 3.14 | AD9: 0.8 | AE9: 0.8 | AF9: =AB9*AC9*AD9*AE9/100 -> 4.82304 | AG9: 240 | AH9: 3.14 | AI9: 1 | AJ9: 0.8 | AK9: =AG9*AH9*AI9*AJ9/100 -> 6.0288 | AM9: 240 | AN9: =R9+25 -> 265 | AO9: 3.14 | AP9: =AN9*AO9/1000 -> 0.8321 | AQ9: 2.45 | AR9: =AP9*AQ9 -> 2.038645 | AS9: 55 | AT9: =AN9+AS9 -> 320 | AU9: =AT9-AM9 -> 80 | AV9: 3.14 | AW9: 0.4 | AX9: 0.8 | AY9: 2 | AZ9: =AT9*AV9*AY9*AW9*AX9/100 -> 6.43072 | BA9: =AZ9+AR9 -> 8.469365 | BB9: 0 | BC9: =BA9+BB9 -> 8.469365 | BE9: 240 | BF9: 240 | BG9: 3.14 | BH9: 0.66 | BI9: =BG9*BF9*BH9/1000 -> 0.497376 | BJ9: =2.5/7.7 -> 0.32467532 | BK9: =BI9+BJ9 -> 0.82205132 | BL9: 240 | BM9: 240 | BN9: 50 | BO9: =BM9+BN9 -> 290 | BP9: 3.14 | BQ9: =BO9*BP9/1000 -> 0.9106 | BR9: 0.66 | BS9: =BQ9*BR9 -> 0.600996 | BT9: 240 | BU9: 240 | BV9: 3.14 | BW9: 1.3 | BX9: =BV9*BU9*BW9/1000 -> 0.97968 | BY9: 0.78 | BZ9: =BX9+BY9 -> 1.75968 | CA9: 240 | CB9: =CA9+50 -> 290 | CC9: =BZ13 -> 2.0046 | CD9: 240 | CE9: 0.96 | CF9: 0.68 | CG9: =CE9+CF9 -> 1.64 | CH9: Ø240Son kapama İzoleli | CI9: 2.412 | CJ9: Ø240Standart Düz Modül 250 mm | CK9: 2.512 | CL9: 240 | CM9: 240 | CN9: 3.14 | CO9: =6/7.3 -> 0.82191781 | CP9: =CM9*CN9*CO9/1000 -> 0.61939726 | CR9: 240 | CS9: =$CQ$2*CR9/1000 -> 1.92 | CT9: 2 | CU9: =CS9+CT9 -> 3.92
A10: 60 | B10: 1 | C10: =B10*C2 -> 6.5 | F10: 250 | G10: 3.14 | H10: 0.25 | I10: =G10*F10*H10/1000 -> 0.19625 | J10: =BC10 -> 8.747255 | K10: =H10*J10 -> 2.1868138 | L10: 250 | M10: 250 | N10: 3.14 | O10: 0.4 | P10: 0.8 | Q10: =M10*N10*O10*P10/100 -> 2.512 | R10: 250 | S10: 3.14 | T10: 0.5 | U10: 0.8 | V10: =R10*S10*T10*U10/100 -> 3.14 | W10: 250 | X10: 3.14 | Y10: 0.6 | Z10: 0.8 | AA10: =W10*X10*Y10*Z10/100 -> 3.768 | AB10: 250 | AC10: 3.14 | AD10: 0.8 | AE10: 0.8 | AF10: =AB10*AC10*AD10*AE10/100 -> 5.024 | AG10: 250 | AH10: 3.14 | AI10: 1 | AJ10: 0.8 | AK10: =AG10*AH10*AI10*AJ10/100 -> 6.28 | AM10: 250 | AN10: =R10+25 -> 275 | AO10: 3.14 | AP10: =AN10*AO10/1000 -> 0.8635 | AQ10: 2.45 | AR10: =AP10*AQ10 -> 2.115575 | AS10: 55 | AT10: =AN10+AS10 -> 330 | AU10: =AT10-AM10 -> 80 | AV10: 3.14 | AW10: 0.4 | AX10: 0.8 | AY10: 2 | AZ10: =AT10*AV10*AY10*AW10*AX10/100 -> 6.63168 | BA10: =AZ10+AR10 -> 8.747255 | BB10: 0 | BC10: =BA10+BB10 -> 8.747255 | BE10: 250 | BF10: 250 | BG10: 3.14 | BH10: 0.66 | BI10: =BG10*BF10*BH10/1000 -> 0.5181 | BJ10: =2.5/7.7 -> 0.32467532 | BK10: =BI10+BJ10 -> 0.84277532 | BL10: 250 | BM10: 250 | BN10: 50 | BO10: =BM10+BN10 -> 300 | BP10: 3.14 | BQ10: =BO10*BP10/1000 -> 0.942 | BR10: 0.66 | BS10: =BQ10*BR10 -> 0.62172 | BT10: 250 | BU10: 250 | BV10: 3.14 | BW10: 1.3 | BX10: =BV10*BU10*BW10/1000 -> 1.0205 | BY10: 0.78 | BZ10: =BX10+BY10 -> 1.8005 | CA10: 250 | CB10: =CA10+50 -> 300 | CC10: =BZ13 -> 2.0046 | CD10: 250 | CE10: 1 | CF10: 0.68 | CG10: =CE10+CF10 -> 1.68 | CH10: Ø250Son kapama İzoleli | CI10: 2.512 | CJ10: Ø250Standart Düz Modül 250 mm | CK10: 2.512 | CL10: 250 | CM10: 250 | CN10: 3.14 | CO10: =6/7.3 -> 0.82191781 | CP10: =CM10*CN10*CO10/1000 -> 0.64520548 | CR10: 250 | CS10: =$CQ$2*CR10/1000 -> 2 | CT10: 2 | CU10: =CS10+CT10 -> 4
A11: 90 | B11: 1 | C11: =B11*C2 -> 6.5 | F11: 260 | G11: 3.14 | H11: 0.25 | I11: =G11*F11*H11/1000 -> 0.2041 | J11: =BC11 -> 9.025145 | K11: =H11*J11 -> 2.2562863 | L11: 260 | M11: 260 | N11: 3.14 | O11: 0.4 | P11: 0.8 | Q11: =M11*N11*O11*P11/100 -> 2.61248 | R11: 260 | S11: 3.14 | T11: 0.5 | U11: 0.8 | V11: =R11*S11*T11*U11/100 -> 3.2656 | W11: 260 | X11: 3.14 | Y11: 0.6 | Z11: 0.8 | AA11: =W11*X11*Y11*Z11/100 -> 3.91872 | AB11: 260 | AC11: 3.14 | AD11: 0.8 | AE11: 0.8 | AF11: =AB11*AC11*AD11*AE11/100 -> 5.22496 | AG11: 260 | AH11: 3.14 | AI11: 1 | AJ11: 0.8 | AK11: =AG11*AH11*AI11*AJ11/100 -> 6.5312 | AM11: 260 | AN11: =R11+25 -> 285 | AO11: 3.14 | AP11: =AN11*AO11/1000 -> 0.8949 | AQ11: 2.45 | AR11: =AP11*AQ11 -> 2.192505 | AS11: 55 | AT11: =AN11+AS11 -> 340 | AU11: =AT11-AM11 -> 80 | AV11: 3.14 | AW11: 0.4 | AX11: 0.8 | AY11: 2 | AZ11: =AT11*AV11*AY11*AW11*AX11/100 -> 6.83264 | BA11: =AZ11+AR11 -> 9.025145 | BB11: 0 | BC11: =BA11+BB11 -> 9.025145 | BE11: 260 | BF11: 260 | BG11: 3.14 | BH11: 0.66 | BI11: =BG11*BF11*BH11/1000 -> 0.538824 | BJ11: =2.5/7.7 -> 0.32467532 | BK11: =BI11+BJ11 -> 0.86349932 | BL11: 260 | BM11: 260 | BN11: 50 | BO11: =BM11+BN11 -> 310 | BP11: 3.14 | BQ11: =BO11*BP11/1000 -> 0.9734 | BR11: 0.66 | BS11: =BQ11*BR11 -> 0.642444 | BT11: 260 | BU11: 260 | BV11: 3.14 | BW11: 1.3 | BX11: =BV11*BU11*BW11/1000 -> 1.06132 | BY11: 0.78 | BZ11: =BX11+BY11 -> 1.84132 | CA11: 260 | CB11: =CA11+50 -> 310 | CC11: =BZ14 -> 2.08624 | CD11: 260 | CE11: 1.12 | CF11: 0.68 | CG11: =CE11+CF11 -> 1.8 | CH11: Ø260Son kapama İzoleli | CI11: 2.512 | CJ11: Ø260Standart Düz Modül 250 mm | CK11: 2.813 | CL11: 260 | CM11: 260 | CN11: 3.14 | CO11: =6/7.3 -> 0.82191781 | CP11: =CM11*CN11*CO11/1000 -> 0.6710137 | CR11: 260 | CS11: =$CQ$2*CR11/1000 -> 2.08 | CT11: 2 | CU11: =CS11+CT11 -> 4.08
F12: 280 | G12: 3.14 | H12: 0.25 | I12: =G12*F12*H12/1000 -> 0.2198 | J12: =BC12 -> 9.580925 | K12: =H12*J12 -> 2.3952313 | L12: 280 | M12: 280 | N12: 3.14 | O12: 0.4 | P12: 0.8 | Q12: =M12*N12*O12*P12/100 -> 2.81344 | R12: 280 | S12: 3.14 | T12: 0.5 | U12: 0.8 | V12: =R12*S12*T12*U12/100 -> 3.5168 | W12: 280 | X12: 3.14 | Y12: 0.6 | Z12: 0.8 | AA12: =W12*X12*Y12*Z12/100 -> 4.22016 | AB12: 280 | AC12: 3.14 | AD12: 0.8 | AE12: 0.8 | AF12: =AB12*AC12*AD12*AE12/100 -> 5.62688 | AG12: 280 | AH12: 3.14 | AI12: 1 | AJ12: 0.8 | AK12: =AG12*AH12*AI12*AJ12/100 -> 7.0336 | AM12: 280 | AN12: =R12+25 -> 305 | AO12: 3.14 | AP12: =AN12*AO12/1000 -> 0.9577 | AQ12: 2.45 | AR12: =AP12*AQ12 -> 2.346365 | AS12: 55 | AT12: =AN12+AS12 -> 360 | AU12: =AT12-AM12 -> 80 | AV12: 3.14 | AW12: 0.4 | AX12: 0.8 | AY12: 2 | AZ12: =AT12*AV12*AY12*AW12*AX12/100 -> 7.23456 | BA12: =AZ12+AR12 -> 9.580925 | BB12: 0 | BC12: =BA12+BB12 -> 9.580925 | BE12: 280 | BF12: 280 | BG12: 3.14 | BH12: 0.66 | BI12: =BG12*BF12*BH12/1000 -> 0.580272 | BJ12: =2.5/7.7 -> 0.32467532 | BK12: =BI12+BJ12 -> 0.90494732 | BL12: 280 | BM12: 280 | BN12: 50 | BO12: =BM12+BN12 -> 330 | BP12: 3.14 | BQ12: =BO12*BP12/1000 -> 1.0362 | BR12: 0.66 | BS12: =BQ12*BR12 -> 0.683892 | BT12: 280 | BU12: 280 | BV12: 3.14 | BW12: 1.3 | BX12: =BV12*BU12*BW12/1000 -> 1.14296 | BY12: 0.78 | BZ12: =BX12+BY12 -> 1.92296 | CA12: 280 | CB12: =CA12+50 -> 330 | CC12: =BZ15 -> 2.2087 | CD12: 280 | CE12: 1.12 | CF12: 0.68 | CG12: =CE12+CF12 -> 1.8 | CH12: Ø280Son kapama İzoleli | CI12: 2.813 | CJ12: Ø280Standart Düz Modül 250 mm | CK12: 3.014 | CL12: 280 | CM12: 280 | CN12: 3.14 | CO12: =6/7.3 -> 0.82191781 | CP12: =CM12*CN12*CO12/1000 -> 0.72263014 | CR12: 280 | CS12: =$CQ$2*CR12/1000 -> 2.24 | CT12: 2 | CU12: =CS12+CT12 -> 4.24
F13: 300 | G13: 3.14 | H13: 0.25 | I13: =G13*F13*H13/1000 -> 0.2355 | J13: =BC13 -> 10.136705 | K13: =H13*J13 -> 2.5341763 | L13: 300 | M13: 300 | N13: 3.14 | O13: 0.4 | P13: 0.8 | Q13: =M13*N13*O13*P13/100 -> 3.0144 | R13: 300 | S13: 3.14 | T13: 0.5 | U13: 0.8 | V13: =R13*S13*T13*U13/100 -> 3.768 | W13: 300 | X13: 3.14 | Y13: 0.6 | Z13: 0.8 | AA13: =W13*X13*Y13*Z13/100 -> 4.5216 | AB13: 300 | AC13: 3.14 | AD13: 0.8 | AE13: 0.8 | AF13: =AB13*AC13*AD13*AE13/100 -> 6.0288 | AG13: 300 | AH13: 3.14 | AI13: 1 | AJ13: 0.8 | AK13: =AG13*AH13*AI13*AJ13/100 -> 7.536 | AM13: 300 | AN13: =R13+25 -> 325 | AO13: 3.14 | AP13: =AN13*AO13/1000 -> 1.0205 | AQ13: 2.45 | AR13: =AP13*AQ13 -> 2.500225 | AS13: 55 | AT13: =AN13+AS13 -> 380 | AU13: =AT13-AM13 -> 80 | AV13: 3.14 | AW13: 0.4 | AX13: 0.8 | AY13: 2 | AZ13: =AT13*AV13*AY13*AW13*AX13/100 -> 7.63648 | BA13: =AZ13+AR13 -> 10.136705 | BB13: 0 | BC13: =BA13+BB13 -> 10.136705 | BE13: 300 | BF13: 300 | BG13: 3.14 | BH13: 0.66 | BI13: =BG13*BF13*BH13/1000 -> 0.62172 | BJ13: =2.5/7.7 -> 0.32467532 | BK13: =BI13+BJ13 -> 0.94639532 | BL13: 300 | BM13: 300 | BN13: 50 | BO13: =BM13+BN13 -> 350 | BP13: 3.14 | BQ13: =BO13*BP13/1000 -> 1.099 | BR13: 0.66 | BS13: =BQ13*BR13 -> 0.72534 | BT13: 300 | BU13: 300 | BV13: 3.14 | BW13: 1.3 | BX13: =BV13*BU13*BW13/1000 -> 1.2246 | BY13: 0.78 | BZ13: =BX13+BY13 -> 2.0046 | CA13: 300 | CB13: =CA13+50 -> 350 | CC13: =BZ15 -> 2.2087 | CD13: 300 | CE13: 1.12 | CF13: 0.68 | CG13: =CE13+CF13 -> 1.8 | CH13: Ø300Son kapama İzoleli | CI13: 3.014 | CJ13: Ø300Standart Düz Modül 250 mm | CK13: 3.215 | CL13: 300 | CM13: 300 | CN13: 3.14 | CO13: =6/7.3 -> 0.82191781 | CP13: =CM13*CN13*CO13/1000 -> 0.77424658 | CR13: 300 | CS13: =$CQ$2*CR13/1000 -> 2.4 | CT13: 2 | CU13: =CS13+CT13 -> 4.4
F14: 320 | G14: 3.14 | H14: 0.25 | I14: =G14*F14*H14/1000 -> 0.2512 | J14: =BC14 -> 10.692485 | K14: =H14*J14 -> 2.6731213 | L14: 320 | M14: 320 | N14: 3.14 | O14: 0.4 | P14: 0.8 | Q14: =M14*N14*O14*P14/100 -> 3.21536 | R14: 320 | S14: 3.14 | T14: 0.5 | U14: 0.8 | V14: =R14*S14*T14*U14/100 -> 4.0192 | W14: 320 | X14: 3.14 | Y14: 0.6 | Z14: 0.8 | AA14: =W14*X14*Y14*Z14/100 -> 4.82304 | AB14: 320 | AC14: 3.14 | AD14: 0.8 | AE14: 0.8 | AF14: =AB14*AC14*AD14*AE14/100 -> 6.43072 | AG14: 320 | AH14: 3.14 | AI14: 1 | AJ14: 0.8 | AK14: =AG14*AH14*AI14*AJ14/100 -> 8.0384 | AM14: 320 | AN14: =R14+25 -> 345 | AO14: 3.14 | AP14: =AN14*AO14/1000 -> 1.0833 | AQ14: 2.45 | AR14: =AP14*AQ14 -> 2.654085 | AS14: 55 | AT14: =AN14+AS14 -> 400 | AU14: =AT14-AM14 -> 80 | AV14: 3.14 | AW14: 0.4 | AX14: 0.8 | AY14: 2 | AZ14: =AT14*AV14*AY14*AW14*AX14/100 -> 8.0384 | BA14: =AZ14+AR14 -> 10.692485 | BB14: 0 | BC14: =BA14+BB14 -> 10.692485 | BE14: 320 | BF14: 320 | BG14: 3.14 | BH14: 0.66 | BI14: =BG14*BF14*BH14/1000 -> 0.663168 | BJ14: =2.5/7.7 -> 0.32467532 | BK14: =BI14+BJ14 -> 0.98784332 | BL14: 320 | BM14: 320 | BN14: 50 | BO14: =BM14+BN14 -> 370 | BP14: 3.14 | BQ14: =BO14*BP14/1000 -> 1.1618 | BR14: 0.66 | BS14: =BQ14*BR14 -> 0.766788 | BT14: 320 | BU14: 320 | BV14: 3.14 | BW14: 1.3 | BX14: =BV14*BU14*BW14/1000 -> 1.30624 | BY14: 0.78 | BZ14: =BX14+BY14 -> 2.08624 | CA14: 320 | CB14: =CA14+50 -> 370 | CC14: =BZ16 -> 2.37198 | CD14: 320 | CE14: 1.28 | CF14: 0.68 | CG14: =CE14+CF14 -> 1.96 | CH14: Ø320Son kapama İzoleli | CI14: 3.215 | CJ14: Ø320Standart Düz Modül 250 mm | CK14: 3.517 | CL14: 320 | CM14: 320 | CN14: 3.14 | CO14: =6/7.3 -> 0.82191781 | CP14: =CM14*CN14*CO14/1000 -> 0.82586301 | CR14: 320 | CS14: =$CQ$2*CR14/1000 -> 2.56 | CT14: 2 | CU14: =CS14+CT14 -> 4.56
F15: 350 | G15: 3.14 | H15: 0.25 | I15: =G15*F15*H15/1000 -> 0.27475 | J15: =BC15 -> 11.526155 | K15: =H15*J15 -> 2.8815388 | L15: 350 | M15: 350 | N15: 3.14 | O15: 0.4 | P15: 0.8 | Q15: =M15*N15*O15*P15/100 -> 3.5168 | R15: 350 | S15: 3.14 | T15: 0.5 | U15: 0.8 | V15: =R15*S15*T15*U15/100 -> 4.396 | W15: 350 | X15: 3.14 | Y15: 0.6 | Z15: 0.8 | AA15: =W15*X15*Y15*Z15/100 -> 5.2752 | AB15: 350 | AC15: 3.14 | AD15: 0.8 | AE15: 0.8 | AF15: =AB15*AC15*AD15*AE15/100 -> 7.0336 | AG15: 350 | AH15: 3.14 | AI15: 1 | AJ15: 0.8 | AK15: =AG15*AH15*AI15*AJ15/100 -> 8.792 | AM15: 350 | AN15: =R15+25 -> 375 | AO15: 3.14 | AP15: =AN15*AO15/1000 -> 1.1775 | AQ15: 2.45 | AR15: =AP15*AQ15 -> 2.884875 | AS15: 55 | AT15: =AN15+AS15 -> 430 | AU15: =AT15-AM15 -> 80 | AV15: 3.14 | AW15: 0.4 | AX15: 0.8 | AY15: 2 | AZ15: =AT15*AV15*AY15*AW15*AX15/100 -> 8.64128 | BA15: =AZ15+AR15 -> 11.526155 | BB15: 0 | BC15: =BA15+BB15 -> 11.526155 | BE15: 350 | BF15: 350 | BG15: 3.14 | BH15: 0.66 | BI15: =BG15*BF15*BH15/1000 -> 0.72534 | BJ15: =2.5/7.7 -> 0.32467532 | BK15: =BI15+BJ15 -> 1.0500153 | BL15: 350 | BM15: 350 | BN15: 50 | BO15: =BM15+BN15 -> 400 | BP15: 3.14 | BQ15: =BO15*BP15/1000 -> 1.256 | BR15: 0.66 | BS15: =BQ15*BR15 -> 0.82896 | BT15: 350 | BU15: 350 | BV15: 3.14 | BW15: 1.3 | BX15: =BV15*BU15*BW15/1000 -> 1.4287 | BY15: 0.78 | BZ15: =BX15+BY15 -> 2.2087 | CA15: 350 | CB15: =CA15+50 -> 400 | CC15: =BZ17 -> 2.4128 | CD15: 350 | CE15: 1.28 | CF15: 0.68 | CG15: =CE15+CF15 -> 1.96 | CH15: Ø350Son kapama İzoleli | CI15: 3.517 | CJ15: Ø350Standart Düz Modül 250 mm | CK15: 3.919 | CL15: 350 | CM15: 350 | CN15: 3.14 | CO15: =6/7.3 -> 0.82191781 | CP15: =CM15*CN15*CO15/1000 -> 0.90328767 | CR15: 350 | CS15: =$CQ$2*CR15/1000 -> 2.8 | CT15: 2 | CU15: =CS15+CT15 -> 4.8
F16: 380 | G16: 3.14 | H16: 0.25 | I16: =G16*F16*H16/1000 -> 0.2983 | J16: =BC16 -> 12.359825 | K16: =H16*J16 -> 3.0899563 | L16: 380 | M16: 380 | N16: 3.14 | O16: 0.4 | P16: 0.8 | Q16: =M16*N16*O16*P16/100 -> 3.81824 | R16: 380 | S16: 3.14 | T16: 0.5 | U16: 0.8 | V16: =R16*S16*T16*U16/100 -> 4.7728 | W16: 380 | X16: 3.14 | Y16: 0.6 | Z16: 0.8 | AA16: =W16*X16*Y16*Z16/100 -> 5.72736 | AB16: 380 | AC16: 3.14 | AD16: 0.8 | AE16: 0.8 | AF16: =AB16*AC16*AD16*AE16/100 -> 7.63648 | AG16: 380 | AH16: 3.14 | AI16: 1 | AJ16: 0.8 | AK16: =AG16*AH16*AI16*AJ16/100 -> 9.5456 | AM16: 380 | AN16: =R16+25 -> 405 | AO16: 3.14 | AP16: =AN16*AO16/1000 -> 1.2717 | AQ16: 2.45 | AR16: =AP16*AQ16 -> 3.115665 | AS16: 55 | AT16: =AN16+AS16 -> 460 | AU16: =AT16-AM16 -> 80 | AV16: 3.14 | AW16: 0.4 | AX16: 0.8 | AY16: 2 | AZ16: =AT16*AV16*AY16*AW16*AX16/100 -> 9.24416 | BA16: =AZ16+AR16 -> 12.359825 | BB16: 0 | BC16: =BA16+BB16 -> 12.359825 | BE16: 390 | BF16: 390 | BG16: 3.14 | BH16: 0.66 | BI16: =BG16*BF16*BH16/1000 -> 0.808236 | BJ16: =2.5/7.7 -> 0.32467532 | BK16: =BI16+BJ16 -> 1.1329113 | BL16: 390 | BM16: 390 | BN16: 50 | BO16: =BM16+BN16 -> 440 | BP16: 3.14 | BQ16: =BO16*BP16/1000 -> 1.3816 | BR16: 0.66 | BS16: =BQ16*BR16 -> 0.911856 | BT16: 390 | BU16: 390 | BV16: 3.14 | BW16: 1.3 | BX16: =BV16*BU16*BW16/1000 -> 1.59198 | BY16: 0.78 | BZ16: =BX16+BY16 -> 2.37198 | CA16: 390 | CB16: =CA16+50 -> 440 | CC16: 2.4128 | CD16: 400 | CE16: 1.44 | CF16: 0.68 | CG16: =CE16+CF16 -> 2.12 | CH16: Ø400Son kapama İzoleli | CI16: 3.919 | CJ16: Ø390Standart Düz Modül 250 mm | CK16: 4.522 | CL16: 390 | CM16: 390 | CN16: 3.14 | CO16: =6/7.3 -> 0.82191781 | CP16: =CM16*CN16*CO16/1000 -> 1.0065205 | CR16: 380 | CS16: =$CQ$2*CR16/1000 -> 3.04 | CT16: 2 | CU16: =CS16+CT16 -> 5.04
F17: 400 | G17: 3.14 | H17: 0.25 | I17: =G17*F17*H17/1000 -> 0.314 | J17: =BC17 -> 12.915605 | K17: =H17*J17 -> 3.2289013 | L17: 400 | M17: 400 | N17: 3.14 | O17: 0.4 | P17: 0.8 | Q17: =M17*N17*O17*P17/100 -> 4.0192 | R17: 400 | S17: 3.14 | T17: 0.5 | U17: 0.8 | V17: =R17*S17*T17*U17/100 -> 5.024 | W17: 400 | X17: 3.14 | Y17: 0.6 | Z17: 0.8 | AA17: =W17*X17*Y17*Z17/100 -> 6.0288 | AB17: 400 | AC17: 3.14 | AD17: 0.8 | AE17: 0.8 | AF17: =AB17*AC17*AD17*AE17/100 -> 8.0384 | AG17: 400 | AH17: 3.14 | AI17: 1 | AJ17: 0.8 | AK17: =AG17*AH17*AI17*AJ17/100 -> 10.048 | AM17: 400 | AN17: =R17+25 -> 425 | AO17: 3.14 | AP17: =AN17*AO17/1000 -> 1.3345 | AQ17: 2.45 | AR17: =AP17*AQ17 -> 3.269525 | AS17: 55 | AT17: =AN17+AS17 -> 480 | AU17: =AT17-AM17 -> 80 | AV17: 3.14 | AW17: 0.4 | AX17: 0.8 | AY17: 2 | AZ17: =AT17*AV17*AY17*AW17*AX17/100 -> 9.64608 | BA17: =AZ17+AR17 -> 12.915605 | BB17: 0 | BC17: =BA17+BB17 -> 12.915605 | BE17: 400 | BF17: 400 | BG17: 3.14 | BH17: 0.66 | BI17: =BG17*BF17*BH17/1000 -> 0.82896 | BJ17: =2.5/7.7 -> 0.32467532 | BK17: =BI17+BJ17 -> 1.1536353 | BL17: 400 | BM17: 400 | BN17: 50 | BO17: =BM17+BN17 -> 450 | BP17: 3.14 | BQ17: =BO17*BP17/1000 -> 1.413 | BR17: 0.66 | BS17: =BQ17*BR17 -> 0.93258 | BT17: 400 | BU17: 400 | BV17: 3.14 | BW17: 1.3 | BX17: =BV17*BU17*BW17/1000 -> 1.6328 | BY17: 0.78 | BZ17: =BX17+BY17 -> 2.4128 | CA17: 400 | CB17: =CA17+50 -> 450 | CC17: =BZ18 -> 2.6169 | CD17: 450 | CE17: 2 | CF17: 0.68 | CG17: =CE17+CF17 -> 2.68 | CH17: Ø450Son kapama İzoleli | CI17: 4.522 | CJ17: Ø450Standart Düz Modül 250 mm | CK17: 5.024 | CL17: 400 | CM17: 400 | CN17: 3.14 | CO17: =6/7.3 -> 0.82191781 | CP17: =CM17*CN17*CO17/1000 -> 1.0323288 | CR17: 400 | CS17: =$CQ$2*CR17/1000 -> 3.2 | CT17: 2 | CU17: =CS17+CT17 -> 5.2
F18: 450 | G18: 3.14 | H18: 0.25 | I18: =G18*F18*H18/1000 -> 0.35325 | J18: =BC18 -> 14.305055 | K18: =H18*J18 -> 3.5762638 | L18: 450 | M18: 450 | N18: 3.14 | O18: 0.4 | P18: 0.8 | Q18: =M18*N18*O18*P18/100 -> 4.5216 | R18: 450 | S18: 3.14 | T18: 0.5 | U18: 0.8 | V18: =R18*S18*T18*U18/100 -> 5.652 | W18: 450 | X18: 3.14 | Y18: 0.6 | Z18: 0.8 | AA18: =W18*X18*Y18*Z18/100 -> 6.7824 | AB18: 450 | AC18: 3.14 | AD18: 0.8 | AE18: 0.8 | AF18: =AB18*AC18*AD18*AE18/100 -> 9.0432 | AG18: 450 | AH18: 3.14 | AI18: 1 | AJ18: 0.8 | AK18: =AG18*AH18*AI18*AJ18/100 -> 11.304 | AM18: 450 | AN18: =R18+25 -> 475 | AO18: 3.14 | AP18: =AN18*AO18/1000 -> 1.4915 | AQ18: 2.45 | AR18: =AP18*AQ18 -> 3.654175 | AS18: 55 | AT18: =AN18+AS18 -> 530 | AU18: =AT18-AM18 -> 80 | AV18: 3.14 | AW18: 0.4 | AX18: 0.8 | AY18: 2 | AZ18: =AT18*AV18*AY18*AW18*AX18/100 -> 10.65088 | BA18: =AZ18+AR18 -> 14.305055 | BB18: 0 | BC18: =BA18+BB18 -> 14.305055 | BE18: 450 | BF18: 450 | BG18: 3.14 | BH18: 0.66 | BI18: =BG18*BF18*BH18/1000 -> 0.93258 | BJ18: =2.5/7.7 -> 0.32467532 | BK18: =BI18+BJ18 -> 1.2572553 | BL18: 450 | BM18: 450 | BN18: 50 | BO18: =BM18+BN18 -> 500 | BP18: 3.14 | BQ18: =BO18*BP18/1000 -> 1.57 | BR18: 0.66 | BS18: =BQ18*BR18 -> 1.0362 | BT18: 450 | BU18: 450 | BV18: 3.14 | BW18: 1.3 | BX18: =BV18*BU18*BW18/1000 -> 1.8369 | BY18: 0.78 | BZ18: =BX18+BY18 -> 2.6169 | CA18: 450 | CB18: =CA18+50 -> 500 | CC18: =BZ19 -> 2.821 | CD18: 500 | CE18: 2.2 | CF18: 0.68 | CG18: =CE18+CF18 -> 2.88 | CH18: Ø500Son kapama İzoleli | CI18: 5.024 | CJ18: Ø500Standart Düz Modül 250 mm | CK18: 5.526 | CL18: 450 | CM18: 450 | CN18: 3.14 | CO18: =6/7.3 -> 0.82191781 | CP18: =CM18*CN18*CO18/1000 -> 1.1613699 | CR18: 450 | CS18: =$CQ$2*CR18/1000 -> 3.6 | CT18: 2 | CU18: =CS18+CT18 -> 5.6
F19: 500 | G19: 3.14 | H19: 0.25 | I19: =G19*F19*H19/1000 -> 0.3925 | J19: =BC19 -> 18.608425 | K19: =H19*J19 -> 4.6521063 | L19: 500 | M19: 500 | N19: 3.14 | O19: 0.4 | P19: 0.8 | Q19: =M19*N19*O19*P19/100 -> 5.024 | R19: 500 | S19: 3.14 | T19: 0.5 | U19: 0.8 | V19: =R19*S19*T19*U19/100 -> 6.28 | W19: 500 | X19: 3.14 | Y19: 0.6 | Z19: 0.8 | AA19: =W19*X19*Y19*Z19/100 -> 7.536 | AB19: 500 | AC19: 3.14 | AD19: 0.8 | AE19: 0.8 | AF19: =AB19*AC19*AD19*AE19/100 -> 10.048 | AG19: 500 | AH19: 3.14 | AI19: 1 | AJ19: 0.8 | AK19: =AG19*AH19*AI19*AJ19/100 -> 12.56 | AM19: 500 | AN19: =R19+25 -> 525 | AO19: 3.14 | AP19: =AN19*AO19/1000 -> 1.6485 | AQ19: 2.45 | AR19: =AP19*AQ19 -> 4.038825 | AS19: 55 | AT19: =AN19+AS19 -> 580 | AU19: =AT19-AM19 -> 80 | AV19: 3.14 | AW19: 0.5 | AX19: 0.8 | AY19: 2 | AZ19: =AT19*AV19*AY19*AW19*AX19/100 -> 14.5696 | BA19: =AZ19+AR19 -> 18.608425 | BB19: 0 | BC19: =BA19+BB19 -> 18.608425 | BE19: 500 | BF19: 500 | BG19: 3.14 | BH19: 0.66 | BI19: =BG19*BF19*BH19/1000 -> 1.0362 | BJ19: =2.5/7.7 -> 0.32467532 | BK19: =BI19+BJ19 -> 1.3608753 | BL19: 500 | BM19: 500 | BN19: 50 | BO19: =BM19+BN19 -> 550 | BP19: 3.14 | BQ19: =BO19*BP19/1000 -> 1.727 | BR19: 0.66 | BS19: =BQ19*BR19 -> 1.13982 | BT19: 500 | BU19: 500 | BV19: 3.14 | BW19: 1.3 | BX19: =BV19*BU19*BW19/1000 -> 2.041 | BY19: 0.78 | BZ19: =BX19+BY19 -> 2.821 | CA19: 500 | CB19: =CA19+50 -> 550 | CC19: =BZ20 -> 3.0251 | CD19: 550 | CE19: 2.5 | CF19: 0.68 | CG19: =CE19+CF19 -> 3.18 | CI19: 5.526 | CJ19: Ø550Standart Düz Modül 250 mm | CK19: 5.526 | CL19: 500 | CM19: 500 | CN19: 3.14 | CO19: =6/7.3 -> 0.82191781 | CP19: =CM19*CN19*CO19/1000 -> 1.290411 | CR19: 500 | CS19: =$CQ$2*CR19/1000 -> 4 | CT19: 2 | CU19: =CS19+CT19 -> 6
F20: 550 | G20: 3.14 | H20: 0.25 | I20: =G20*F20*H20/1000 -> 0.43175 | J20: =BC20 -> 20.249075 | K20: =H20*J20 -> 5.0622688 | L20: 550 | M20: 550 | N20: 3.14 | O20: 0.4 | P20: 0.8 | Q20: =M20*N20*O20*P20/100 -> 5.5264 | R20: 550 | S20: 3.14 | T20: 0.5 | U20: 0.8 | V20: =R20*S20*T20*U20/100 -> 6.908 | W20: 550 | X20: 3.14 | Y20: 0.6 | Z20: 0.8 | AA20: =W20*X20*Y20*Z20/100 -> 8.2896 | AB20: 550 | AC20: 3.14 | AD20: 0.8 | AE20: 0.8 | AF20: =AB20*AC20*AD20*AE20/100 -> 11.0528 | AG20: 550 | AH20: 3.14 | AI20: 1 | AJ20: 0.8 | AK20: =AG20*AH20*AI20*AJ20/100 -> 13.816 | AM20: 550 | AN20: =R20+25 -> 575 | AO20: 3.14 | AP20: =AN20*AO20/1000 -> 1.8055 | AQ20: 2.45 | AR20: =AP20*AQ20 -> 4.423475 | AS20: 55 | AT20: =AN20+AS20 -> 630 | AU20: =AT20-AM20 -> 80 | AV20: 3.14 | AW20: 0.5 | AX20: 0.8 | AY20: 2 | AZ20: =AT20*AV20*AY20*AW20*AX20/100 -> 15.8256 | BA20: =AZ20+AR20 -> 20.249075 | BB20: 0 | BC20: =BA20+BB20 -> 20.249075 | BE20: 550 | BF20: 550 | BG20: 3.14 | BH20: 0.66 | BI20: =BG20*BF20*BH20/1000 -> 1.13982 | BJ20: =2.5/7.7 -> 0.32467532 | BK20: =BI20+BJ20 -> 1.4644953 | BL20: 550 | BM20: 550 | BN20: 50 | BO20: =BM20+BN20 -> 600 | BP20: 3.14 | BQ20: =BO20*BP20/1000 -> 1.884 | BR20: 0.66 | BS20: =BQ20*BR20 -> 1.24344 | BT20: 550 | BU20: 550 | BV20: 3.14 | BW20: 1.3 | BX20: =BV20*BU20*BW20/1000 -> 2.2451 | BY20: 0.78 | BZ20: =BX20+BY20 -> 3.0251 | CA20: 550 | CB20: =CA20+50 -> 600 | CC20: =BZ21 -> 3.2292 | CD20: 600 | CE20: 2.8 | CF20: 0.68 | CG20: =CE20+CF20 -> 3.48 | CI20: 6.029 | CJ20: Ø600Standart Düz Modül 250 mm | CK20: 6.029 | CL20: 550 | CM20: 550 | CN20: 3.14 | CO20: =6/7.3 -> 0.82191781 | CP20: =CM20*CN20*CO20/1000 -> 1.4194521 | CR20: 550 | CS20: =$CQ$2*CR20/1000 -> 4.4 | CT20: 2 | CU20: =CS20+CT20 -> 6.4
F21: 600 | G21: 3.14 | H21: 0.25 | I21: =G21*F21*H21/1000 -> 0.471 | J21: =BC21 -> 21.889725 | K21: =H21*J21 -> 5.4724313 | L21: 600 | M21: 600 | N21: 3.14 | O21: 0.4 | P21: 0.8 | Q21: =M21*N21*O21*P21/100 -> 6.0288 | R21: 600 | S21: 3.14 | T21: 0.5 | U21: 0.8 | V21: =R21*S21*T21*U21/100 -> 7.536 | W21: 600 | X21: 3.14 | Y21: 0.6 | Z21: 0.8 | AA21: =W21*X21*Y21*Z21/100 -> 9.0432 | AB21: 600 | AC21: 3.14 | AD21: 0.8 | AE21: 0.8 | AF21: =AB21*AC21*AD21*AE21/100 -> 12.0576 | AG21: 600 | AH21: 3.14 | AI21: 1 | AJ21: 0.8 | AK21: =AG21*AH21*AI21*AJ21/100 -> 15.072 | AM21: 600 | AN21: =R21+25 -> 625 | AO21: 3.14 | AP21: =AN21*AO21/1000 -> 1.9625 | AQ21: 2.45 | AR21: =AP21*AQ21 -> 4.808125 | AS21: 55 | AT21: =AN21+AS21 -> 680 | AU21: =AT21-AM21 -> 80 | AV21: 3.14 | AW21: 0.5 | AX21: 0.8 | AY21: 2 | AZ21: =AT21*AV21*AY21*AW21*AX21/100 -> 17.0816 | BA21: =AZ21+AR21 -> 21.889725 | BB21: 0 | BC21: =BA21+BB21 -> 21.889725 | BE21: 600 | BF21: 600 | BG21: 3.14 | BH21: 0.66 | BI21: =BG21*BF21*BH21/1000 -> 1.24344 | BJ21: =2.5/7.7 -> 0.32467532 | BK21: =BI21+BJ21 -> 1.5681153 | BL21: 600 | BM21: 600 | BN21: 50 | BO21: =BM21+BN21 -> 650 | BP21: 3.14 | BQ21: =BO21*BP21/1000 -> 2.041 | BR21: 0.66 | BS21: =BQ21*BR21 -> 1.34706 | BT21: 600 | BU21: 600 | BV21: 3.14 | BW21: 1.3 | BX21: =BV21*BU21*BW21/1000 -> 2.4492 | BY21: 0.78 | BZ21: =BX21+BY21 -> 3.2292 | CA21: 600 | CB21: =CA21+50 -> 650 | CC21: =BZ22 -> 3.4333 | CD21: 650 | CE21: 3.1 | CF21: 0.68 | CG21: =CE21+CF21 -> 3.78 | CI21: 6.5312 | CJ21: Ø650Standart Düz Modül 250 mm | CK21: 6.5312 | CL21: 600 | CM21: 600 | CN21: 3.14 | CO21: =6/7.3 -> 0.82191781 | CP21: =CM21*CN21*CO21/1000 -> 1.5484932 | CR21: 600 | CS21: =$CQ$2*CR21/1000 -> 4.8 | CT21: 2 | CU21: =CS21+CT21 -> 6.8
F22: 650 | G22: 3.14 | H22: 0.25 | I22: =G22*F22*H22/1000 -> 0.51025 | J22: =BC22 -> 23.530375 | K22: =H22*J22 -> 5.8825938 | L22: 650 | M22: 650 | N22: 3.14 | O22: 0.4 | P22: 0.8 | Q22: =M22*N22*O22*P22/100 -> 6.5312 | R22: 650 | S22: 3.14 | T22: 0.5 | U22: 0.8 | V22: =R22*S22*T22*U22/100 -> 8.164 | W22: 650 | X22: 3.14 | Y22: 0.6 | Z22: 0.8 | AA22: =W22*X22*Y22*Z22/100 -> 9.7968 | AB22: 650 | AC22: 3.14 | AD22: 0.8 | AE22: 0.8 | AF22: =AB22*AC22*AD22*AE22/100 -> 13.0624 | AG22: 650 | AH22: 3.14 | AI22: 1 | AJ22: 0.8 | AK22: =AG22*AH22*AI22*AJ22/100 -> 16.328 | AM22: 650 | AN22: =R22+25 -> 675 | AO22: 3.14 | AP22: =AN22*AO22/1000 -> 2.1195 | AQ22: 2.45 | AR22: =AP22*AQ22 -> 5.192775 | AS22: 55 | AT22: =AN22+AS22 -> 730 | AU22: =AT22-AM22 -> 80 | AV22: 3.14 | AW22: 0.5 | AX22: 0.8 | AY22: 2 | AZ22: =AT22*AV22*AY22*AW22*AX22/100 -> 18.3376 | BA22: =AZ22+AR22 -> 23.530375 | BB22: 0 | BC22: =BA22+BB22 -> 23.530375 | BE22: 650 | BF22: 650 | BG22: 3.14 | BH22: 0.66 | BI22: =BG22*BF22*BH22/1000 -> 1.34706 | BJ22: =2.5/7.7 -> 0.32467532 | BK22: =BI22+BJ22 -> 1.6717353 | BL22: 650 | BM22: 650 | BN22: 50 | BO22: =BM22+BN22 -> 700 | BP22: 3.14 | BQ22: =BO22*BP22/1000 -> 2.198 | BR22: 0.66 | BS22: =BQ22*BR22 -> 1.45068 | BT22: 650 | BU22: 650 | BV22: 3.14 | BW22: 1.3 | BX22: =BV22*BU22*BW22/1000 -> 2.6533 | BY22: 0.78 | BZ22: =BX22+BY22 -> 3.4333 | CA22: 650 | CB22: =CA22+50 -> 700 | CC22: =BZ23 -> 3.6374 | CD22: 700 | CE22: 3.4 | CF22: 0.68 | CG22: =CE22+CF22 -> 4.08 | CI22: 7.0336 | CJ22: Ø700Standart Düz Modül 250 mm | CK22: 7.0336 | CL22: 650 | CM22: 650 | CN22: 3.14 | CO22: =6/7.3 -> 0.82191781 | CP22: =CM22*CN22*CO22/1000 -> 1.6775342 | CR22: 650 | CS22: =$CQ$2*CR22/1000 -> 5.2 | CT22: 2 | CU22: =CS22+CT22 -> 7.2
F23: 700 | G23: 3.14 | H23: 0.25 | I23: =G23*F23*H23/1000 -> 0.5495 | J23: =BC23 -> 25.171025 | K23: =H23*J23 -> 6.2927563 | L23: 700 | M23: 700 | N23: 3.14 | O23: 0.4 | P23: 0.8 | Q23: =M23*N23*O23*P23/100 -> 7.0336 | R23: 700 | S23: 3.14 | T23: 0.5 | U23: 0.8 | V23: =R23*S23*T23*U23/100 -> 8.792 | W23: 700 | X23: 3.14 | Y23: 0.6 | Z23: 0.8 | AA23: =W23*X23*Y23*Z23/100 -> 10.5504 | AB23: 700 | AC23: 3.14 | AD23: 0.8 | AE23: 0.8 | AF23: =AB23*AC23*AD23*AE23/100 -> 14.0672 | AG23: 700 | AH23: 3.14 | AI23: 1 | AJ23: 0.8 | AK23: =AG23*AH23*AI23*AJ23/100 -> 17.584 | AM23: 700 | AN23: =R23+25 -> 725 | AO23: 3.14 | AP23: =AN23*AO23/1000 -> 2.2765 | AQ23: 2.45 | AR23: =AP23*AQ23 -> 5.577425 | AS23: 55 | AT23: =AN23+AS23 -> 780 | AU23: =AT23-AM23 -> 80 | AV23: 3.14 | AW23: 0.5 | AX23: 0.8 | AY23: 2 | AZ23: =AT23*AV23*AY23*AW23*AX23/100 -> 19.5936 | BA23: =AZ23+AR23 -> 25.171025 | BB23: 0 | BC23: =BA23+BB23 -> 25.171025 | BE23: 700 | BF23: 700 | BG23: 3.14 | BH23: 0.66 | BI23: =BG23*BF23*BH23/1000 -> 1.45068 | BJ23: =2.5/7.7 -> 0.32467532 | BK23: =BI23+BJ23 -> 1.7753553 | BL23: 700 | BM23: 700 | BN23: 50 | BO23: =BM23+BN23 -> 750 | BP23: 3.14 | BQ23: =BO23*BP23/1000 -> 2.355 | BR23: 0.66 | BS23: =BQ23*BR23 -> 1.5543 | BT23: 700 | BU23: 700 | BV23: 3.14 | BW23: 1.3 | BX23: =BV23*BU23*BW23/1000 -> 2.8574 | BY23: 0.78 | BZ23: =BX23+BY23 -> 3.6374 | CA23: 700 | CB23: =CA23+50 -> 750 | CC23: =BZ24 -> 3.8415 | CD23: 750 | CE23: 3.7 | CF23: 0.68 | CG23: =CE23+CF23 -> 4.38 | CI23: 7.536 | CJ23: Ø750Standart Düz Modül 250 mm | CK23: 7.536 | CL23: 700 | CM23: 700 | CN23: 3.14 | CO23: =6/7.3 -> 0.82191781 | CP23: =CM23*CN23*CO23/1000 -> 1.8065753 | CR23: 700 | CS23: =$CQ$2*CR23/1000 -> 5.6 | CT23: 2 | CU23: =CS23+CT23 -> 7.6
F24: 750 | G24: 3.14 | H24: 0.25 | I24: =G24*F24*H24/1000 -> 0.58875 | J24: =BC24 -> 26.811675 | K24: =H24*J24 -> 6.7029188 | L24: 750 | M24: 750 | N24: 3.14 | O24: 0.4 | P24: 0.8 | Q24: =M24*N24*O24*P24/100 -> 7.536 | R24: 750 | S24: 3.14 | T24: 0.5 | U24: 0.8 | V24: =R24*S24*T24*U24/100 -> 9.42 | W24: 750 | X24: 3.14 | Y24: 0.6 | Z24: 0.8 | AA24: =W24*X24*Y24*Z24/100 -> 11.304 | AB24: 750 | AC24: 3.14 | AD24: 0.8 | AE24: 0.8 | AF24: =AB24*AC24*AD24*AE24/100 -> 15.072 | AG24: 750 | AH24: 3.14 | AI24: 1 | AJ24: 0.8 | AK24: =AG24*AH24*AI24*AJ24/100 -> 18.84 | AM24: 750 | AN24: =R24+25 -> 775 | AO24: 3.14 | AP24: =AN24*AO24/1000 -> 2.4335 | AQ24: 2.45 | AR24: =AP24*AQ24 -> 5.962075 | AS24: 55 | AT24: =AN24+AS24 -> 830 | AU24: =AT24-AM24 -> 80 | AV24: 3.14 | AW24: 0.5 | AX24: 0.8 | AY24: 2 | AZ24: =AT24*AV24*AY24*AW24*AX24/100 -> 20.8496 | BA24: =AZ24+AR24 -> 26.811675 | BB24: 0 | BC24: =BA24+BB24 -> 26.811675 | BE24: 750 | BF24: 750 | BG24: 3.14 | BH24: 0.66 | BI24: =BG24*BF24*BH24/1000 -> 1.5543 | BJ24: =2.5/7.7 -> 0.32467532 | BK24: =BI24+BJ24 -> 1.8789753 | BL24: 750 | BM24: 750 | BN24: 50 | BO24: =BM24+BN24 -> 800 | BP24: 3.14 | BQ24: =BO24*BP24/1000 -> 2.512 | BR24: 0.66 | BS24: =BQ24*BR24 -> 1.65792 | BT24: 750 | BU24: 750 | BV24: 3.14 | BW24: 1.3 | BX24: =BV24*BU24*BW24/1000 -> 3.0615 | BY24: 0.78 | BZ24: =BX24+BY24 -> 3.8415 | CA24: 750 | CB24: =CA24+50 -> 800 | CC24: =BZ25 -> 4.0456 | CD24: 800 | CE24: 4 | CF24: 0.68 | CG24: =CE24+CF24 -> 4.68 | CI24: 8.0384 | CJ24: Ø800Standart Düz Modül 250 mm | CK24: 8.0384 | CL24: 750 | CM24: 750 | CN24: 3.14 | CO24: =6/7.3 -> 0.82191781 | CP24: =CM24*CN24*CO24/1000 -> 1.9356164 | CR24: 750 | CS24: =$CQ$2*CR24/1000 -> 6 | CT24: 2 | CU24: =CS24+CT24 -> 8
F25: 800 | G25: 3.14 | H25: 0.25 | I25: =G25*F25*H25/1000 -> 0.628 | J25: =BC25 -> 28.452325 | K25: =H25*J25 -> 7.1130813 | L25: 800 | M25: 800 | N25: 3.14 | O25: 0.4 | P25: 0.8 | Q25: =M25*N25*O25*P25/100 -> 8.0384 | R25: 800 | S25: 3.14 | T25: 0.5 | U25: 0.8 | V25: =R25*S25*T25*U25/100 -> 10.048 | W25: 800 | X25: 3.14 | Y25: 0.6 | Z25: 0.8 | AA25: =W25*X25*Y25*Z25/100 -> 12.0576 | AB25: 800 | AC25: 3.14 | AD25: 0.8 | AE25: 0.8 | AF25: =AB25*AC25*AD25*AE25/100 -> 16.0768 | AG25: 800 | AH25: 3.14 | AI25: 1 | AJ25: 0.8 | AK25: =AG25*AH25*AI25*AJ25/100 -> 20.096 | AM25: 800 | AN25: =R25+25 -> 825 | AO25: 3.14 | AP25: =AN25*AO25/1000 -> 2.5905 | AQ25: 2.45 | AR25: =AP25*AQ25 -> 6.346725 | AS25: 55 | AT25: =AN25+AS25 -> 880 | AU25: =AT25-AM25 -> 80 | AV25: 3.14 | AW25: 0.5 | AX25: 0.8 | AY25: 2 | AZ25: =AT25*AV25*AY25*AW25*AX25/100 -> 22.1056 | BA25: =AZ25+AR25 -> 28.452325 | BB25: 0 | BC25: =BA25+BB25 -> 28.452325 | BE25: 800 | BF25: 800 | BG25: 3.14 | BH25: 0.66 | BI25: =BG25*BF25*BH25/1000 -> 1.65792 | BJ25: =2.5/7.7 -> 0.32467532 | BK25: =BI25+BJ25 -> 1.9825953 | BL25: 800 | BM25: 800 | BN25: 50 | BO25: =BM25+BN25 -> 850 | BP25: 3.14 | BQ25: =BO25*BP25/1000 -> 2.669 | BR25: 0.66 | BS25: =BQ25*BR25 -> 1.76154 | BT25: 800 | BU25: 800 | BV25: 3.14 | BW25: 1.3 | BX25: =BV25*BU25*BW25/1000 -> 3.2656 | BY25: 0.78 | BZ25: =BX25+BY25 -> 4.0456 | CA25: 800 | CB25: =CA25+50 -> 850 | CC25: =BZ26 -> 4.2497 | CD25: 850 | CE25: 4.3 | CF25: 0.68 | CG25: =CE25+CF25 -> 4.98 | CI25: 8.5408 | CJ25: Ø850Standart Düz Modül 250 mm | CK25: 8.5408 | CL25: 800 | CM25: 800 | CN25: 3.14 | CO25: =6/7.3 -> 0.82191781 | CP25: =CM25*CN25*CO25/1000 -> 2.0646575 | CR25: 800 | CS25: =$CQ$2*CR25/1000 -> 6.4 | CT25: 2 | CU25: =CS25+CT25 -> 8.4
F26: 850 | G26: 3.14 | H26: 0.25 | I26: =G26*F26*H26/1000 -> 0.66725 | J26: =BC26 -> 30.092975 | K26: =H26*J26 -> 7.5232438 | L26: 850 | M26: 850 | N26: 3.14 | O26: 0.4 | P26: 0.8 | Q26: =M26*N26*O26*P26/100 -> 8.5408 | R26: 850 | S26: 3.14 | T26: 0.5 | U26: 0.8 | V26: =R26*S26*T26*U26/100 -> 10.676 | W26: 850 | X26: 3.14 | Y26: 0.6 | Z26: 0.8 | AA26: =W26*X26*Y26*Z26/100 -> 12.8112 | AB26: 850 | AC26: 3.14 | AD26: 0.8 | AE26: 0.8 | AF26: =AB26*AC26*AD26*AE26/100 -> 17.0816 | AG26: 850 | AH26: 3.14 | AI26: 1 | AJ26: 0.8 | AK26: =AG26*AH26*AI26*AJ26/100 -> 21.352 | AM26: 850 | AN26: =R26+25 -> 875 | AO26: 3.14 | AP26: =AN26*AO26/1000 -> 2.7475 | AQ26: 2.45 | AR26: =AP26*AQ26 -> 6.731375 | AS26: 55 | AT26: =AN26+AS26 -> 930 | AU26: =AT26-AM26 -> 80 | AV26: 3.14 | AW26: 0.5 | AX26: 0.8 | AY26: 2 | AZ26: =AT26*AV26*AY26*AW26*AX26/100 -> 23.3616 | BA26: =AZ26+AR26 -> 30.092975 | BB26: 0 | BC26: =BA26+BB26 -> 30.092975 | BE26: 850 | BF26: 850 | BG26: 3.14 | BH26: 0.66 | BI26: =BG26*BF26*BH26/1000 -> 1.76154 | BJ26: =2.5/7.7 -> 0.32467532 | BK26: =BI26+BJ26 -> 2.0862153 | BL26: 850 | BM26: 850 | BN26: 50 | BO26: =BM26+BN26 -> 900 | BP26: 3.14 | BQ26: =BO26*BP26/1000 -> 2.826 | BR26: 0.66 | BS26: =BQ26*BR26 -> 1.86516 | BT26: 850 | BU26: 850 | BV26: 3.14 | BW26: 1.3 | BX26: =BV26*BU26*BW26/1000 -> 3.4697 | BY26: 0.78 | BZ26: =BX26+BY26 -> 4.2497 | CA26: 850 | CB26: =CA26+50 -> 900 | CC26: =BZ27 -> 4.4538 | CD26: 900 | CE26: 4.6 | CF26: 0.68 | CG26: =CE26+CF26 -> 5.28 | CI26: 9.0432 | CJ26: Ø900Standart Düz Modül 250 mm | CK26: 9.0432 | CL26: 850 | CM26: 850 | CN26: 3.14 | CO26: =6/7.3 -> 0.82191781 | CP26: =CM26*CN26*CO26/1000 -> 2.1936986 | CR26: 850 | CS26: =$CQ$2*CR26/1000 -> 6.8 | CT26: 2 | CU26: =CS26+CT26 -> 8.8
F27: 900 | G27: 3.14 | H27: 0.25 | I27: =G27*F27*H27/1000 -> 0.7065 | J27: =BC27 -> 31.733625 | K27: =H27*J27 -> 7.9334063 | L27: 900 | M27: 900 | N27: 3.14 | O27: 0.4 | P27: 0.8 | Q27: =M27*N27*O27*P27/100 -> 9.0432 | R27: 900 | S27: 3.14 | T27: 0.5 | U27: 0.8 | V27: =R27*S27*T27*U27/100 -> 11.304 | W27: 900 | X27: 3.14 | Y27: 0.6 | Z27: 0.8 | AA27: =W27*X27*Y27*Z27/100 -> 13.5648 | AB27: 900 | AC27: 3.14 | AD27: 0.8 | AE27: 0.8 | AF27: =AB27*AC27*AD27*AE27/100 -> 18.0864 | AG27: 900 | AH27: 3.14 | AI27: 1 | AJ27: 0.8 | AK27: =AG27*AH27*AI27*AJ27/100 -> 22.608 | AM27: 900 | AN27: =R27+25 -> 925 | AO27: 3.14 | AP27: =AN27*AO27/1000 -> 2.9045 | AQ27: 2.45 | AR27: =AP27*AQ27 -> 7.116025 | AS27: 55 | AT27: =AN27+AS27 -> 980 | AU27: =AT27-AM27 -> 80 | AV27: 3.14 | AW27: 0.5 | AX27: 0.8 | AY27: 2 | AZ27: =AT27*AV27*AY27*AW27*AX27/100 -> 24.6176 | BA27: =AZ27+AR27 -> 31.733625 | BB27: 0 | BC27: =BA27+BB27 -> 31.733625 | BE27: 900 | BF27: 900 | BG27: 3.14 | BH27: 0.66 | BI27: =BG27*BF27*BH27/1000 -> 1.86516 | BJ27: =2.5/7.7 -> 0.32467532 | BK27: =BI27+BJ27 -> 2.1898353 | BL27: 900 | BM27: 900 | BN27: 50 | BO27: =BM27+BN27 -> 950 | BP27: 3.14 | BQ27: =BO27*BP27/1000 -> 2.983 | BR27: 0.66 | BS27: =BQ27*BR27 -> 1.96878 | BT27: 900 | BU27: 900 | BV27: 3.14 | BW27: 1.3 | BX27: =BV27*BU27*BW27/1000 -> 3.6738 | BY27: 0.78 | BZ27: =BX27+BY27 -> 4.4538 | CA27: 900 | CB27: =CA27+50 -> 950 | CC27: =BZ28 -> 4.6579 | CD27: 950 | CE27: 4.9 | CF27: 0.68 | CG27: =CE27+CF27 -> 5.58 | CI27: 9.5456 | CJ27: Ø950Standart Düz Modül 250 mm | CK27: 9.5456 | CL27: 900 | CM27: 900 | CN27: 3.14 | CO27: =6/7.3 -> 0.82191781 | CP27: =CM27*CN27*CO27/1000 -> 2.3227397 | CR27: 900 | CS27: =$CQ$2*CR27/1000 -> 7.2 | CT27: 2 | CU27: =CS27+CT27 -> 9.2
F28: 950 | G28: 3.14 | H28: 0.25 | I28: =G28*F28*H28/1000 -> 0.74575 | J28: =BC28 -> 33.374275 | K28: =H28*J28 -> 8.3435688 | L28: 950 | M28: 950 | N28: 3.14 | O28: 0.4 | P28: 0.8 | Q28: =M28*N28*O28*P28/100 -> 9.5456 | R28: 950 | S28: 3.14 | T28: 0.5 | U28: 0.8 | V28: =R28*S28*T28*U28/100 -> 11.932 | W28: 950 | X28: 3.14 | Y28: 0.6 | Z28: 0.8 | AA28: =W28*X28*Y28*Z28/100 -> 14.3184 | AB28: 950 | AC28: 3.14 | AD28: 0.8 | AE28: 0.8 | AF28: =AB28*AC28*AD28*AE28/100 -> 19.0912 | AG28: 950 | AH28: 3.14 | AI28: 1 | AJ28: 0.8 | AK28: =AG28*AH28*AI28*AJ28/100 -> 23.864 | AM28: 950 | AN28: =R28+25 -> 975 | AO28: 3.14 | AP28: =AN28*AO28/1000 -> 3.0615 | AQ28: 2.45 | AR28: =AP28*AQ28 -> 7.500675 | AS28: 55 | AT28: =AN28+AS28 -> 1030 | AU28: =AT28-AM28 -> 80 | AV28: 3.14 | AW28: 0.5 | AX28: 0.8 | AY28: 2 | AZ28: =AT28*AV28*AY28*AW28*AX28/100 -> 25.8736 | BA28: =AZ28+AR28 -> 33.374275 | BB28: 0 | BC28: =BA28+BB28 -> 33.374275 | BE28: 950 | BF28: 950 | BG28: 3.14 | BH28: 0.66 | BI28: =BG28*BF28*BH28/1000 -> 1.96878 | BJ28: =2.5/7.7 -> 0.32467532 | BK28: =BI28+BJ28 -> 2.2934553 | BL28: 950 | BM28: 950 | BN28: 50 | BO28: =BM28+BN28 -> 1000 | BP28: 3.14 | BQ28: =BO28*BP28/1000 -> 3.14 | BR28: 0.66 | BS28: =BQ28*BR28 -> 2.0724 | BT28: 950 | BU28: 950 | BV28: 3.14 | BW28: 1.3 | BX28: =BV28*BU28*BW28/1000 -> 3.8779 | BY28: 0.78 | BZ28: =BX28+BY28 -> 4.6579 | CA28: 950 | CB28: =CA28+50 -> 1000 | CC28: =BZ29 -> 4.862 | CD28: 1000 | CE28: 5.2 | CF28: 0.68 | CG28: =CE28+CF28 -> 5.88 | CI28: 10.048 | CJ28: Ø1000Standart Düz Modül 250 mm | CK28: 10.048 | CL28: 950 | CM28: 950 | CN28: 3.14 | CO28: =6/7.3 -> 0.82191781 | CP28: =CM28*CN28*CO28/1000 -> 2.4517808 | CR28: 950 | CS28: =$CQ$2*CR28/1000 -> 7.6 | CT28: 2 | CU28: =CS28+CT28 -> 9.6
F29: 1000 | G29: 3.14 | H29: 0.25 | I29: =G29*F29*H29/1000 -> 0.785 | J29: =BC29 -> 35.014925 | K29: =H29*J29 -> 8.7537313 | L29: 1000 | M29: 1000 | N29: 3.14 | O29: 0.4 | P29: 0.8 | Q29: =M29*N29*O29*P29/100 -> 10.048 | R29: 1000 | S29: 3.14 | T29: 0.5 | U29: 0.8 | V29: =R29*S29*T29*U29/100 -> 12.56 | W29: 1000 | X29: 3.14 | Y29: 0.6 | Z29: 0.8 | AA29: =W29*X29*Y29*Z29/100 -> 15.072 | AB29: 1000 | AC29: 3.14 | AD29: 0.8 | AE29: 0.8 | AF29: =AB29*AC29*AD29*AE29/100 -> 20.096 | AG29: 1000 | AH29: 3.14 | AI29: 1 | AJ29: 0.8 | AK29: =AG29*AH29*AI29*AJ29/100 -> 25.12 | AM29: 1000 | AN29: =R29+25 -> 1025 | AO29: 3.14 | AP29: =AN29*AO29/1000 -> 3.2185 | AQ29: 2.45 | AR29: =AP29*AQ29 -> 7.885325 | AS29: 55 | AT29: =AN29+AS29 -> 1080 | AU29: =AT29-AM29 -> 80 | AV29: 3.14 | AW29: 0.5 | AX29: 0.8 | AY29: 2 | AZ29: =AT29*AV29*AY29*AW29*AX29/100 -> 27.1296 | BA29: =AZ29+AR29 -> 35.014925 | BB29: 0 | BC29: =BA29+BB29 -> 35.014925 | BE29: 1000 | BF29: 1000 | BG29: 3.14 | BH29: 0.66 | BI29: =BG29*BF29*BH29/1000 -> 2.0724 | BJ29: =2.5/7.7 -> 0.32467532 | BK29: =BI29+BJ29 -> 2.3970753 | BL29: 1000 | BM29: 1000 | BN29: 50 | BO29: =BM29+BN29 -> 1050 | BP29: 3.14 | BQ29: =BO29*BP29/1000 -> 3.297 | BR29: 0.66 | BS29: =BQ29*BR29 -> 2.17602 | BT29: 1000 | BU29: 1000 | BV29: 3.14 | BW29: 1.3 | BX29: =BV29*BU29*BW29/1000 -> 4.082 | BY29: 0.78 | BZ29: =BX29+BY29 -> 4.862 | CA29: 1000 | CB29: =CA29+50 -> 1050 | CC29: =BZ30 -> 5.0661 | CD29: 1050 | CE29: 5.5 | CF29: 0.68 | CG29: =CE29+CF29 -> 6.18 | CI29: 10.5504 | CJ29: Ø1050Standart Düz Modül 250 mm | CK29: 10.5504 | CL29: 1000 | CM29: 1000 | CN29: 3.14 | CO29: =6/7.3 -> 0.82191781 | CP29: =CM29*CN29*CO29/1000 -> 2.5808219 | CR29: 1000 | CS29: =$CQ$2*CR29/1000 -> 8 | CT29: 2 | CU29: =CS29+CT29 -> 10
F30: 1050 | G30: 3.14 | H30: 0.25 | I30: =G30*F30*H30/1000 -> 0.82425 | J30: =BC30 -> 36.655575 | K30: =H30*J30 -> 9.1638938 | L30: 1050 | M30: 1050 | N30: 3.14 | O30: 0.4 | P30: 0.8 | Q30: =M30*N30*O30*P30/100 -> 10.5504 | R30: 1050 | S30: 3.14 | T30: 0.5 | U30: 0.8 | V30: =R30*S30*T30*U30/100 -> 13.188 | W30: 1050 | X30: 3.14 | Y30: 0.6 | Z30: 0.8 | AA30: =W30*X30*Y30*Z30/100 -> 15.8256 | AB30: 1050 | AC30: 3.14 | AD30: 0.8 | AE30: 0.8 | AF30: =AB30*AC30*AD30*AE30/100 -> 21.1008 | AG30: 1050 | AH30: 3.14 | AI30: 1 | AJ30: 0.8 | AK30: =AG30*AH30*AI30*AJ30/100 -> 26.376 | AM30: 1050 | AN30: =R30+25 -> 1075 | AO30: 3.14 | AP30: =AN30*AO30/1000 -> 3.3755 | AQ30: 2.45 | AR30: =AP30*AQ30 -> 8.269975 | AS30: 55 | AT30: =AN30+AS30 -> 1130 | AU30: =AT30-AM30 -> 80 | AV30: 3.14 | AW30: 0.5 | AX30: 0.8 | AY30: 2 | AZ30: =AT30*AV30*AY30*AW30*AX30/100 -> 28.3856 | BA30: =AZ30+AR30 -> 36.655575 | BB30: 0 | BC30: =BA30+BB30 -> 36.655575 | BE30: 1050 | BF30: 1050 | BG30: 3.14 | BH30: 0.66 | BI30: =BG30*BF30*BH30/1000 -> 2.17602 | BJ30: =2.5/7.7 -> 0.32467532 | BK30: =BI30+BJ30 -> 2.5006953 | BL30: 1050 | BM30: 1050 | BN30: 50 | BO30: =BM30+BN30 -> 1100 | BP30: 3.14 | BQ30: =BO30*BP30/1000 -> 3.454 | BR30: 0.66 | BS30: =BQ30*BR30 -> 2.27964 | BT30: 1050 | BU30: 1050 | BV30: 3.14 | BW30: 1.3 | BX30: =BV30*BU30*BW30/1000 -> 4.2861 | BY30: 0.78 | BZ30: =BX30+BY30 -> 5.0661 | CA30: 1050 | CB30: =CA30+50 -> 1100 | CC30: =BZ31 -> 5.2702 | CD30: 1100 | CE30: 5.8 | CF30: 0.68 | CG30: =CE30+CF30 -> 6.48 | CI30: 11.0528 | CJ30: Ø1100Standart Düz Modül 250 mm | CK30: 11.0528 | CL30: 1050 | CM30: 1050 | CN30: 3.14 | CO30: =6/7.3 -> 0.82191781 | CP30: =CM30*CN30*CO30/1000 -> 2.709863 | CR30: 1050 | CS30: =$CQ$2*CR30/1000 -> 8.4 | CT30: 2 | CU30: =CS30+CT30 -> 10.4
... F32: 1150 | G32: 3.14 | H32: 0.25 | I32: =G32*F32*H32/1000 -> 0.90275 | J32: =BC32 -> 39.936875 | K32: =H32*J32 -> 9.9842188 | L32: 1150 | M32: 1150 | N32: 3.14 | O32: 0.4 | P32: 0.8 | Q32: =M32*N32*O32*P32/100 -> 11.5552 | R32: 1150 | S32: 3.14 | T32: 0.5 | U32: 0.8 | V32: =R32*S32*T32*U32/100 -> 14.444 | W32: 1150 | X32: 3.14 | Y32: 0.6 | Z32: 0.8 | AA32: =W32*X32*Y32*Z32/100 -> 17.3328 | AB32: 1150 | AC32: 3.14 | AD32: 0.8 | AE32: 0.8 | AF32: =AB32*AC32*AD32*AE32/100 -> 23.1104 | AG32: 1150 | AH32: 3.14 | AI32: 1 | AJ32: 0.8 | AK32: =AG32*AH32*AI32*AJ32/100 -> 28.888 | AM32: 1150 | AN32: =R32+25 -> 1175 | AO32: 3.14 | AP32: =AN32*AO32/1000 -> 3.6895 | AQ32: 2.45 | AR32: =AP32*AQ32 -> 9.039275 | AS32: 55 | AT32: =AN32+AS32 -> 1230 | AU32: =AT32-AM32 -> 80 | AV32: 3.14 | AW32: 0.5 | AX32: 0.8 | AY32: 2 | AZ32: =AT32*AV32*AY32*AW32*AX32/100 -> 30.8976 | BA32: =AZ32+AR32 -> 39.936875 | BB32: 0 | BC32: =BA32+BB32 -> 39.936875 | BE32: 1150 | BF32: 1150 | BG32: 3.14 | BH32: 0.66 | BI32: =BG32*BF32*BH32/1000 -> 2.38326 | BJ32: =2.5/7.7 -> 0.32467532 | BK32: =BI32+BJ32 -> 2.7079353 | BL32: 1150 | BM32: 1150 | BN32: 50 | BO32: =BM32+BN32 -> 1200 | BP32: 3.14 | BQ32: =BO32*BP32/1000 -> 3.768 | BR32: 0.66 | BS32: =BQ32*BR32 -> 2.48688 | BT32: 1150 | BU32: 1150 | BV32: 3.14 | BW32: 1.3 | BX32: =BV32*BU32*BW32/1000 -> 4.6943 | BY32: 0.78 | BZ32: =BX32+BY32 -> 5.4743 | CA32: 1150 | CB32: =CA32+50 -> 1200 | CC32: =BZ33 -> 5.6784 | CD32: 1200 | CE32: 6.4 | CF32: 0.68 | CG32: =CE32+CF32 -> 7.08 | CI32: 13.0624 | CJ32: Ø1300Standart Düz Modül 250 mm | CK32: 13.0624 | CL32: 1150 | CM32: 1150 | CN32: 3.14 | CO32: =6/7.3 -> 0.82191781 | CP32: =CM32*CN32*CO32/1000 -> 2.9679452 | CR32: 1150 | CS32: =$CQ$2*CR32/1000 -> 9.2 | CT32: 2 | CU32: =CS32+CT32 -> 11.2
F33: 1200 | G33: 3.14 | H33: 0.25 | I33: =G33*F33*H33/1000 -> 0.942 | J33: =BC33 -> 41.577525 | K33: =H33*J33 -> 10.394381 | L33: 1200 | M33: 1200 | N33: 3.14 | O33: 0.4 | P33: 0.8 | Q33: =M33*N33*O33*P33/100 -> 12.0576 | R33: 1200 | S33: 3.14 | T33: 0.5 | U33: 0.8 | V33: =R33*S33*T33*U33/100 -> 15.072 | W33: 1200 | X33: 3.14 | Y33: 0.6 | Z33: 0.8 | AA33: =W33*X33*Y33*Z33/100 -> 18.0864 | AB33: 1200 | AC33: 3.14 | AD33: 0.8 | AE33: 0.8 | AF33: =AB33*AC33*AD33*AE33/100 -> 24.1152 | AG33: 1200 | AH33: 3.14 | AI33: 1 | AJ33: 0.8 | AK33: =AG33*AH33*AI33*AJ33/100 -> 30.144 | AM33: 1200 | AN33: =R33+25 -> 1225 | AO33: 3.14 | AP33: =AN33*AO33/1000 -> 3.8465 | AQ33: 2.45 | AR33: =AP33*AQ33 -> 9.423925 | AS33: 55 | AT33: =AN33+AS33 -> 1280 | AU33: =AT33-AM33 -> 80 | AV33: 3.14 | AW33: 0.5 | AX33: 0.8 | AY33: 2 | AZ33: =AT33*AV33*AY33*AW33*AX33/100 -> 32.1536 | BA33: =AZ33+AR33 -> 41.577525 | BB33: 0 | BC33: =BA33+BB33 -> 41.577525 | BE33: 1200 | BF33: 1200 | BG33: 3.14 | BH33: 0.66 | BI33: =BG33*BF33*BH33/1000 -> 2.48688 | BJ33: =2.5/7.7 -> 0.32467532 | BK33: =BI33+BJ33 -> 2.8115553 | BL33: 1200 | BM33: 1200 | BN33: 50 | BO33: =BM33+BN33 -> 1250 | BP33: 3.14 | BQ33: =BO33*BP33/1000 -> 3.925 | BR33: 0.66 | BS33: =BQ33*BR33 -> 2.5905 | BT33: 1200 | BU33: 1200 | BV33: 3.14 | BW33: 1.3 | BX33: =BV33*BU33*BW33/1000 -> 4.8984 | BY33: 0.78 | BZ33: =BX33+BY33 -> 5.6784 | CA33: 1200 | CB33: =CA33+50 -> 1250 | CC33: =BZ34 -> 5.8825 | CD33: 1250 | CE33: 6.7 | CF33: 0.68 | CG33: =CE33+CF33 -> 7.38 | CL33: 1200 | CM33: 1200 | CN33: 3.14 | CO33: =6/7.3 -> 0.82191781 | CP33: =CM33*CN33*CO33/1000 -> 3.0969863 | CR33: 1200 | CS33: =$CQ$2*CR33/1000 -> 9.6 | CT33: 2 | CU33: =CS33+CT33 -> 11.6
F34: 1250 | G34: 3.14 | H34: 0.25 | I34: =G34*F34*H34/1000 -> 0.98125 | J34: =BC34 -> 43.218175 | K34: =H34*J34 -> 10.804544 | L34: 1250 | M34: 1250 | N34: 3.14 | O34: 0.4 | P34: 0.8 | Q34: =M34*N34*O34*P34/100 -> 12.56 | R34: 1250 | S34: 3.14 | T34: 0.5 | U34: 0.8 | V34: =R34*S34*T34*U34/100 -> 15.7 | W34: 1250 | X34: 3.14 | Y34: 0.6 | Z34: 0.8 | AA34: =W34*X34*Y34*Z34/100 -> 18.84 | AB34: 1250 | AC34: 3.14 | AD34: 0.8 | AE34: 0.8 | AF34: =AB34*AC34*AD34*AE34/100 -> 25.12 | AG34: 1250 | AH34: 3.14 | AI34: 1 | AJ34: 0.8 | AK34: =AG34*AH34*AI34*AJ34/100 -> 31.4 | AM34: 1250 | AN34: =R34+25 -> 1275 | AO34: 3.14 | AP34: =AN34*AO34/1000 -> 4.0035 | AQ34: 2.45 | AR34: =AP34*AQ34 -> 9.808575 | AS34: 55 | AT34: =AN34+AS34 -> 1330 | AU34: =AT34-AM34 -> 80 | AV34: 3.14 | AW34: 0.5 | AX34: 0.8 | AY34: 2 | AZ34: =AT34*AV34*AY34*AW34*AX34/100 -> 33.4096 | BA34: =AZ34+AR34 -> 43.218175 | BB34: 0 | BC34: =BA34+BB34 -> 43.218175 | BE34: 1250 | BF34: 1250 | BG34: 3.14 | BH34: 0.66 | BI34: =BG34*BF34*BH34/1000 -> 2.5905 | BJ34: =2.5/7.7 -> 0.32467532 | BK34: =BI34+BJ34 -> 2.9151753 | BL34: 1250 | BM34: 1250 | BN34: 50 | BO34: =BM34+BN34 -> 1300 | BP34: 3.14 | BQ34: =BO34*BP34/1000 -> 4.082 | BR34: 0.66 | BS34: =BQ34*BR34 -> 2.69412 | BT34: 1250 | BU34: 1250 | BV34: 3.14 | BW34: 1.3 | BX34: =BV34*BU34*BW34/1000 -> 5.1025 | BY34: 0.78 | BZ34: =BX34+BY34 -> 5.8825 | CA34: 1250 | CB34: =CA34+50 -> 1300 | CC34: =BZ35 -> 6.0866 | CD34: 1300 | CE34: 7 | CF34: 0.68 | CG34: =CE34+CF34 -> 7.68 | CL34: 1250 | CM34: 1250 | CN34: 3.14 | CO34: =6/7.3 -> 0.82191781 | CP34: =CM34*CN34*CO34/1000 -> 3.2260274 | CR34: 1250 | CS34: =$CQ$2*CR34/1000 -> 10 | CT34: 2 | CU34: =CS34+CT34 -> 12
F35: 1300 | G35: 3.14 | H35: 0.25 | I35: =G35*F35*H35/1000 -> 1.0205 | J35: =BC35 -> 44.858825 | K35: =H35*J35 -> 11.214706 | L35: 1300 | M35: 1300 | N35: 3.14 | O35: 0.4 | P35: 0.8 | Q35: =M35*N35*O35*P35/100 -> 13.0624 | R35: 1300 | S35: 3.14 | T35: 0.5 | U35: 0.8 | V35: =R35*S35*T35*U35/100 -> 16.328 | W35: 1300 | X35: 3.14 | Y35: 0.6 | Z35: 0.8 | AA35: =W35*X35*Y35*Z35/100 -> 19.5936 | AB35: 1300 | AC35: 3.14 | AD35: 0.8 | AE35: 0.8 | AF35: =AB35*AC35*AD35*AE35/100 -> 26.1248 | AG35: 1300 | AH35: 3.14 | AI35: 1 | AJ35: 0.8 | AK35: =AG35*AH35*AI35*AJ35/100 -> 32.656 | AM35: 1300 | AN35: =R35+25 -> 1325 | AO35: 3.14 | AP35: =AN35*AO35/1000 -> 4.1605 | AQ35: 2.45 | AR35: =AP35*AQ35 -> 10.193225 | AS35: 55 | AT35: =AN35+AS35 -> 1380 | AU35: =AT35-AM35 -> 80 | AV35: 3.14 | AW35: 0.5 | AX35: 0.8 | AY35: 2 | AZ35: =AT35*AV35*AY35*AW35*AX35/100 -> 34.6656 | BA35: =AZ35+AR35 -> 44.858825 | BB35: 0 | BC35: =BA35+BB35 -> 44.858825 | BE35: 1300 | BF35: 1300 | BG35: 3.14 | BH35: 0.66 | BI35: =BG35*BF35*BH35/1000 -> 2.69412 | BJ35: =2.5/7.7 -> 0.32467532 | BK35: =BI35+BJ35 -> 3.0187953 | BL35: 1300 | BM35: 1300 | BN35: 50 | BO35: =BM35+BN35 -> 1350 | BP35: 3.14 | BQ35: =BO35*BP35/1000 -> 4.239 | BR35: 0.66 | BS35: =BQ35*BR35 -> 2.79774 | BT35: 1300 | BU35: 1300 | BV35: 3.14 | BW35: 1.3 | BX35: =BV35*BU35*BW35/1000 -> 5.3066 | BY35: 0.78 | BZ35: =BX35+BY35 -> 6.0866 | CA35: 1300 | CB35: =CA35+50 -> 1350 | CC35: =BZ35*1.05 -> 6.39093 | CL35: 1300 | CM35: 1300 | CN35: 3.14 | CO35: =6/7.3 -> 0.82191781 | CP35: =CM35*CN35*CO35/1000 -> 3.3550685 | CR35: 1300 | CS35: =$CQ$2*CR35/1000 -> 10.4 | CT35: 2 | CU35: =CS35+CT35 -> 12.4
B37: NOTLAR
A38: 1 | B38: Sehpaların birim fiyatları yazılacak
A39: 2 | B39: Kapaklı temizleme modülleri 50 cm olarak alındı.
A40: 3 | B40: Kapaklı Modül İzoleli ( TEMİZLEME ) izole fiyatı yazılacak mı ?
A41: 4 | B41: Boru contalarının maliyete etkisi diğer moduller uzerine eklenmiştir.
A42: 5 | B42: Dirseklerin metrajları girilecek.
...

Sheet AĞIRLIK
B1: İZOLESİZ | F1: İZOLELİ
A2: SIRA | B2: BORU ÇAPI | D2: SAC KALINLIĞI | F2: BORU ÇAPI | G2: AĞIRLIĞI | H2: SAC KALINLIĞI
A3: =CONCATENATE(B3,"-",D3) -> ø 100-0,4 | B3: ø 100 | C3: ='genel hesap'!J2 -> 1.0048 | D3: 0.4 | F3: ø 100 | G3: 1.809 | H3: 0.4
A4: =CONCATENATE(B4,"-",D4) -> ø 130-0,4 | B4: ø 130 | C4: ='genel hesap'!J3 -> 1.30624 | D4: 0.4 | F4: ø 130 | G4: 2.1
A5: =CONCATENATE(B5,"-",D5) -> ø 140-0,4 | B5: ø 140 | C5: ='genel hesap'!J4 -> 1.40672 | D5: 0.4 | F5: ø 140 | G5: 2.211
A6: =CONCATENATE(B6,"-",D6) -> ø 150-0,4 | B6: ø 150 | C6: ='genel hesap'!J5 -> 1.5072 | D6: 0.4 | F6: ø 150 | G6: 2.311
A7: =CONCATENATE(B7,"-",D7) -> ø 180-0,4 | B7: ø 180 | C7: ='genel hesap'!J6 -> 1.80864 | D7: 0.4 | F7: ø 180 | G7: 2.612
A8: =CONCATENATE(B8,"-",D8) -> ø 200-0,4 | B8: ø 200 | C8: ='genel hesap'!J7 -> 2.0096 | D8: 0.4 | F8: ø 200 | G8: 2.813
A9: =CONCATENATE(B9,"-",D9) -> ø 225-0,4 | B9: ø 225 | C9: ='genel hesap'!J8 -> 2.2608 | D9: 0.4 | F9: ø 225 | G9: 3.065
